Workbook

Sheet Veda
G1: 1-25,36-60 | H1: 8 | I1: 13 | J1: 18 | K1: 23 | L1: 28 | M1: 33 | N1: 38
D2: ="~Inputcell: "&_xlfn.TEXTJOIN(",",TRUE,G1:EE1) -> ~Inputcell: 1-25,36-60,8,13,18,23,28,33,38
D3: 3
D5: =VLOOKUP(D3,$C$9:$E$999,2,FALSE) -> ts_annual | E5: =VLOOKUP(D3,$C$9:$E$999,3,FALSE) -> C3
B7: ~Scenmap
A8: priority | B8: scen | C8: case_no | D8: timeslice | E8: climate | AM8: bio price multiplier
A9: 5 | B9: =VLOOKUP(E9,$AK$9:$AL$15,2,FALSE)&"."&VLOOKUP(D9,$AH$9:$AI$24,2,FALSE) -> e 1.5 deg no OS.xAnn | C9: 1 | D9: =VLOOKUP(AJ9,$AG$9:$AH$22,2,FALSE) -> ts_annual | E9: C1 | G9: Limit warming to 1.5°C (>50%) with no or limited overshoot | AG9: 1 | AH9: ts_annual | AI9: xAnn | AJ9: 1 | AK9: C1 | AL9: e 1.5 deg no OS | AM9: 5
A10: 5 | B10: =VLOOKUP(E10,$AK$9:$AL$15,2,FALSE)&"."&VLOOKUP(D10,$AH$9:$AI$24,2,FALSE) -> d 1.5 deg OS.xAnn | C10: =C9+1 -> 2 | D10: =VLOOKUP(AJ10,$AG$9:$AH$22,2,FALSE) -> ts_annual | E10: C2 | G10: Limit warming to 1.5°C (>67%) with high overshoot | S10: IEA | AG10: 2 | AH10: ts_12t | AI10: x12 | AJ10: 1 | AK10: C2 | AL10: d 1.5 deg OS | AM10: 4
A11: 5 | B11: =VLOOKUP(E11,$AK$9:$AL$15,2,FALSE)&"."&VLOOKUP(D11,$AH$9:$AI$24,2,FALSE) -> c 2 deg (67%).xAnn | C11: =C10+1 -> 3 | D11: =VLOOKUP(AJ11,$AG$9:$AH$22,2,FALSE) -> ts_annual | E11: C3 | G11: Limit warming to 2°C (>67%) with higher action post-2030 | S11: 2022 | AG11: 3 | AH11: ts_012 | AI11: =AH11 -> ts_012 | AJ11: 1 | AK11: C3 | AL11: c 2 deg (67%) | AM11: 3
A12: 5 | B12: =VLOOKUP(E12,$AK$9:$AL$15,2,FALSE)&"."&VLOOKUP(D12,$AH$9:$AI$24,2,FALSE) -> b 2 deg (50%).xAnn | C12: =C11+1 -> 4 | D12: =VLOOKUP(AJ12,$AG$9:$AH$22,2,FALSE) -> ts_annual | E12: C4 | G12: Limit warming to 2°C (>50%) with immediate action | S12: =SUMIFS(iea_data!I3:I9999,iea_data!$B$3:$B$9999,Veda!$S$11)+T28-T29 -> 185.91 | T12: base-year generation (TWh) | AG12: 4 | AH12: ts_030 | AI12: =AH12 -> ts_030 | AJ12: 1 | AK12: C4 | AL12: b 2 deg (50%) | AM12: 3
A13: 5 | B13: =VLOOKUP(E13,$AK$9:$AL$15,2,FALSE)&"."&VLOOKUP(D13,$AH$9:$AI$24,2,FALSE) -> a 3 deg.xAnn | C13: =C12+1 -> 5 | D13: =VLOOKUP(AJ13,$AG$9:$AH$22,2,FALSE) -> ts_annual | E13: C7 | G13: Likely above 3°C warming with limited mitigation | AG13: 5 | AH13: ts_048 | AI13: =AH13 -> ts_048 | AJ13: 1 | AK13: C7 | AL13: a 3 deg | AM13: 1.5
A14: 5 | B14: =VLOOKUP(E14,$AK$9:$AL$15,2,FALSE)&"."&VLOOKUP(D14,$AH$9:$AI$24,2,FALSE) -> e 1.5 deg no OS.x12 | C14: =C13+1 -> 6 | D14: =VLOOKUP(AJ14,$AG$9:$AH$22,2,FALSE) -> ts_12t | E14: =E9 -> C1 | T14: =S12 -> 185.91 | U14: =$S$12*J15 -> 215.6556 | V14: =$S$12*K15 -> 243.5421 | W14: =$S$12*L15 -> 278.865 | X14: =$S$12*M15 -> 319.7652 | Y14: =$S$12*N15 -> 395.9883 | Z14: =$S$12*O15 -> 466.6341 | AG14: 6 | AH14: ts_072 | AI14: =AH14 -> ts_072 | AJ14: =AJ9+1 -> 2
A15: 5 | B15: =VLOOKUP(E15,$AK$9:$AL$15,2,FALSE)&"."&VLOOKUP(D15,$AH$9:$AI$24,2,FALSE) -> d 1.5 deg OS.x12 | C15: =C14+1 -> 7 | D15: =VLOOKUP(AJ15,$AG$9:$AH$22,2,FALSE) -> ts_12t | E15: =E10 -> C2 | G15: Electricity growth relative to 2020 | I15: =SUMIFS(ar6_r10!$F$2:$F$999,ar6_r10!$A$2:$A$999,Veda!$E$5,ar6_r10!$C$2:$C$999,Veda!I$17,ar6_r10!$M$2:$M$999,Veda!$G15) -> 1 | J15: =SUMIFS(ar6_r10!$F$2:$F$999,ar6_r10!$A$2:$A$999,Veda!$E$5,ar6_r10!$C$2:$C$999,Veda!J$17,ar6_r10!$M$2:$M$999,Veda!$G15) -> 1.16 | K15: =SUMIFS(ar6_r10!$F$2:$F$999,ar6_r10!$A$2:$A$999,Veda!$E$5,ar6_r10!$C$2:$C$999,Veda!K$17,ar6_r10!$M$2:$M$999,Veda!$G15) -> 1.31 | L15: =SUMIFS(ar6_r10!$F$2:$F$999,ar6_r10!$A$2:$A$999,Veda!$E$5,ar6_r10!$C$2:$C$999,Veda!L$17,ar6_r10!$M$2:$M$999,Veda!$G15) -> 1.5 | M15: =SUMIFS(ar6_r10!$F$2:$F$999,ar6_r10!$A$2:$A$999,Veda!$E$5,ar6_r10!$C$2:$C$999,Veda!M$17,ar6_r10!$M$2:$M$999,Veda!$G15) -> 1.72 | N15: =SUMIFS(ar6_r10!$F$2:$F$999,ar6_r10!$A$2:$A$999,Veda!$E$5,ar6_r10!$C$2:$C$999,Veda!N$17,ar6_r10!$M$2:$M$999,Veda!$G15) -> 2.13 | O15: =SUMIFS(ar6_r10!$F$2:$F$999,ar6_r10!$A$2:$A$999,Veda!$E$5,ar6_r10!$C$2:$C$999,Veda!O$17,ar6_r10!$M$2:$M$999,Veda!$G15) -> 2.51 | AG15: 7 | AH15: ts_144 | AI15: =AH15 -> ts_144 | AJ15: =AJ10+1 -> 2
A16: 5 | B16: =VLOOKUP(E16,$AK$9:$AL$15,2,FALSE)&"."&VLOOKUP(D16,$AH$9:$AI$24,2,FALSE) -> c 2 deg (67%).x12 | C16: =C15+1 -> 8 | D16: =VLOOKUP(AJ16,$AG$9:$AH$22,2,FALSE) -> ts_12t | E16: =E11 -> C3 | S16: ~TFM_INS-TS | AG16: 8 | AH16: ts_288 | AI16: =AH16 -> ts_288 | AJ16: =AJ11+1 -> 2
A17: 5 | B17: =VLOOKUP(E17,$AK$9:$AL$15,2,FALSE)&"."&VLOOKUP(D17,$AH$9:$AI$24,2,FALSE) -> b 2 deg (50%).x12 | C17: =C16+1 -> 9 | D17: =VLOOKUP(AJ17,$AG$9:$AH$22,2,FALSE) -> ts_12t | E17: =E12 -> C4 | I17: 2020 | J17: =U17 -> 2025 | K17: =V17 -> 2030 | L17: =W17 -> 2035 | M17: =X17 -> 2040 | N17: =Y17 -> 2045 | O17: =Z17 -> 2050 | S17: commodity | T17: 2022 | U17: 2025 | V17: 2030 | W17: 2035 | X17: 2040 | Y17: 2045 | Z17: 2050 | AA17: attribute | AG17: 9 | AH17: s1v1_d | AI17: f2d96 | AJ17: =AJ12+1 -> 2
A18: 5 | B18: =VLOOKUP(E18,$AK$9:$AL$15,2,FALSE)&"."&VLOOKUP(D18,$AH$9:$AI$24,2,FALSE) -> a 3 deg.x12 | C18: =C17+1 -> 10 | D18: =VLOOKUP(AJ18,$AG$9:$AH$22,2,FALSE) -> ts_12t | E18: =E13 -> C7 | G18: Hydrogen as a share of electricity | I18: =SUMIFS(ar6_r10!$F$2:$F$999,ar6_r10!$A$2:$A$999,Veda!$E$5,ar6_r10!$C$2:$C$999,Veda!I$17,ar6_r10!$M$2:$M$999,Veda!$G18) -> 0 | J18: =SUMIFS(ar6_r10!$F$2:$F$999,ar6_r10!$A$2:$A$999,Veda!$E$5,ar6_r10!$C$2:$C$999,Veda!J$17,ar6_r10!$M$2:$M$999,Veda!$G18) -> 0 | K18: =SUMIFS(ar6_r10!$F$2:$F$999,ar6_r10!$A$2:$A$999,Veda!$E$5,ar6_r10!$C$2:$C$999,Veda!K$17,ar6_r10!$M$2:$M$999,Veda!$G18) -> 0 | L18: =SUMIFS(ar6_r10!$F$2:$F$999,ar6_r10!$A$2:$A$999,Veda!$E$5,ar6_r10!$C$2:$C$999,Veda!L$17,ar6_r10!$M$2:$M$999,Veda!$G18) -> 0.01 | M18: =SUMIFS(ar6_r10!$F$2:$F$999,ar6_r10!$A$2:$A$999,Veda!$E$5,ar6_r10!$C$2:$C$999,Veda!M$17,ar6_r10!$M$2:$M$999,Veda!$G18) -> 0.02 | N18: =SUMIFS(ar6_r10!$F$2:$F$999,ar6_r10!$A$2:$A$999,Veda!$E$5,ar6_r10!$C$2:$C$999,Veda!N$17,ar6_r10!$M$2:$M$999,Veda!$G18) -> 0.03 | O18: =SUMIFS(ar6_r10!$F$2:$F$999,ar6_r10!$A$2:$A$999,Veda!$E$5,ar6_r10!$C$2:$C$999,Veda!O$17,ar6_r10!$M$2:$M$999,Veda!$G18) -> 0.03 | S18: hydrogen_allsect | T18: =I18*T$14 -> 0 | U18: =J18*U$14 -> 0 | V18: =K18*V$14 -> 0 | W18: =L18*W$14 -> 2.78865 | X18: =M18*X$14 -> 6.395304 | Y18: =N18*Y$14 -> 11.879649 | Z18: =O18*Z$14 -> 13.999023 | AA18: demand | AG18: 10 | AH18: ts_096 | AI18: e96 | AJ18: =AJ13+1 -> 2
A19: 5 | B19: =VLOOKUP(E19,$AK$9:$AL$15,2,FALSE)&"."&VLOOKUP(D19,$AH$9:$AI$24,2,FALSE) -> e 1.5 deg no OS.ts_012 | C19: =C18+1 -> 11 | D19: =VLOOKUP(AJ19,$AG$9:$AH$22,2,FALSE) -> ts_012 | E19: =E14 -> C1 | G19: Industry electricity share | I19: =SUMIFS(ar6_r10!$F$2:$F$999,ar6_r10!$A$2:$A$999,Veda!$E$5,ar6_r10!$C$2:$C$999,Veda!I$17,ar6_r10!$M$2:$M$999,Veda!$G19) -> 0.46 | J19: =SUMIFS(ar6_r10!$F$2:$F$999,ar6_r10!$A$2:$A$999,Veda!$E$5,ar6_r10!$C$2:$C$999,Veda!J$17,ar6_r10!$M$2:$M$999,Veda!$G19) -> 0.42 | K19: =SUMIFS(ar6_r10!$F$2:$F$999,ar6_r10!$A$2:$A$999,Veda!$E$5,ar6_r10!$C$2:$C$999,Veda!K$17,ar6_r10!$M$2:$M$999,Veda!$G19) -> 0.44 | L19: =SUMIFS(ar6_r10!$F$2:$F$999,ar6_r10!$A$2:$A$999,Veda!$E$5,ar6_r10!$C$2:$C$999,Veda!L$17,ar6_r10!$M$2:$M$999,Veda!$G19) -> 0.43 | M19: =SUMIFS(ar6_r10!$F$2:$F$999,ar6_r10!$A$2:$A$999,Veda!$E$5,ar6_r10!$C$2:$C$999,Veda!M$17,ar6_r10!$M$2:$M$999,Veda!$G19) -> 0.41 | N19: =SUMIFS(ar6_r10!$F$2:$F$999,ar6_r10!$A$2:$A$999,Veda!$E$5,ar6_r10!$C$2:$C$999,Veda!N$17,ar6_r10!$M$2:$M$999,Veda!$G19) -> 0.43 | O19: =SUMIFS(ar6_r10!$F$2:$F$999,ar6_r10!$A$2:$A$999,Veda!$E$5,ar6_r10!$C$2:$C$999,Veda!O$17,ar6_r10!$M$2:$M$999,Veda!$G19) -> 0.39 | S19: elc_industry | T19: =I19*T$14 -> 85.5186 | U19: =J19*U$14 -> 90.575352 | V19: =K19*V$14 -> 107.15852 | W19: =L19*W$14 -> 119.91195 | X19: =M19*X$14 -> 131.10373 | Y19: =N19*Y$14 -> 170.27497 | Z19: =O19*Z$14 -> 181.9873 | AA19: demand | AG19: 11 | AH19: s1p1v1_d | AI19: d9d | AJ19: =AJ14+1 -> 3
A20: 5 | B20: =VLOOKUP(E20,$AK$9:$AL$15,2,FALSE)&"."&VLOOKUP(D20,$AH$9:$AI$24,2,FALSE) -> d 1.5 deg OS.ts_012 | C20: =C19+1 -> 12 | D20: =VLOOKUP(AJ20,$AG$9:$AH$22,2,FALSE) -> ts_012 | E20: =E15 -> C2 | G20: Residential and commercial electricity share | I20: =SUMIFS(ar6_r10!$F$2:$F$999,ar6_r10!$A$2:$A$999,Veda!$E$5,ar6_r10!$C$2:$C$999,Veda!I$17,ar6_r10!$M$2:$M$999,Veda!$G20) -> 0.53 | J20: =SUMIFS(ar6_r10!$F$2:$F$999,ar6_r10!$A$2:$A$999,Veda!$E$5,ar6_r10!$C$2:$C$999,Veda!J$17,ar6_r10!$M$2:$M$999,Veda!$G20) -> 0.56 | K20: =SUMIFS(ar6_r10!$F$2:$F$999,ar6_r10!$A$2:$A$999,Veda!$E$5,ar6_r10!$C$2:$C$999,Veda!K$17,ar6_r10!$M$2:$M$999,Veda!$G20) -> 0.53 | L20: =SUMIFS(ar6_r10!$F$2:$F$999,ar6_r10!$A$2:$A$999,Veda!$E$5,ar6_r10!$C$2:$C$999,Veda!L$17,ar6_r10!$M$2:$M$999,Veda!$G20) -> 0.52 | M20: =SUMIFS(ar6_r10!$F$2:$F$999,ar6_r10!$A$2:$A$999,Veda!$E$5,ar6_r10!$C$2:$C$999,Veda!M$17,ar6_r10!$M$2:$M$999,Veda!$G20) -> 0.52 | N20: =SUMIFS(ar6_r10!$F$2:$F$999,ar6_r10!$A$2:$A$999,Veda!$E$5,ar6_r10!$C$2:$C$999,Veda!N$17,ar6_r10!$M$2:$M$999,Veda!$G20) -> 0.5 | O20: =SUMIFS(ar6_r10!$F$2:$F$999,ar6_r10!$A$2:$A$999,Veda!$E$5,ar6_r10!$C$2:$C$999,Veda!O$17,ar6_r10!$M$2:$M$999,Veda!$G20) -> 0.49 | S20: elc_buildings | T20: =I20*T$14 -> 98.5323 | U20: =J20*U$14 -> 120.76714 | V20: =K20*V$14 -> 129.07731 | W20: =L20*W$14 -> 145.0098 | X20: =M20*X$14 -> 166.2779 | Y20: =N20*Y$14 -> 197.99415 | Z20: =O20*Z$14 -> 228.65071 | AA20: demand | AG20: 12 | AH20: s5p5v5_d | AI20: c15d | AJ20: =AJ15+1 -> 3
A21: 5 | B21: =VLOOKUP(E21,$AK$9:$AL$15,2,FALSE)&"."&VLOOKUP(D21,$AH$9:$AI$24,2,FALSE) -> c 2 deg (67%).ts_012 | C21: =C20+1 -> 13 | D21: =VLOOKUP(AJ21,$AG$9:$AH$22,2,FALSE) -> ts_012 | E21: =E16 -> C3 | G21: Transportation electricity share | I21: =SUMIFS(ar6_r10!$F$2:$F$999,ar6_r10!$A$2:$A$999,Veda!$E$5,ar6_r10!$C$2:$C$999,Veda!I$17,ar6_r10!$M$2:$M$999,Veda!$G21) -> 0.01 | J21: =SUMIFS(ar6_r10!$F$2:$F$999,ar6_r10!$A$2:$A$999,Veda!$E$5,ar6_r10!$C$2:$C$999,Veda!J$17,ar6_r10!$M$2:$M$999,Veda!$G21) -> 0.01 | K21: =SUMIFS(ar6_r10!$F$2:$F$999,ar6_r10!$A$2:$A$999,Veda!$E$5,ar6_r10!$C$2:$C$999,Veda!K$17,ar6_r10!$M$2:$M$999,Veda!$G21) -> 0.02 | L21: =SUMIFS(ar6_r10!$F$2:$F$999,ar6_r10!$A$2:$A$999,Veda!$E$5,ar6_r10!$C$2:$C$999,Veda!L$17,ar6_r10!$M$2:$M$999,Veda!$G21) -> 0.03 | M21: =SUMIFS(ar6_r10!$F$2:$F$999,ar6_r10!$A$2:$A$999,Veda!$E$5,ar6_r10!$C$2:$C$999,Veda!M$17,ar6_r10!$M$2:$M$999,Veda!$G21) -> 0.04 | N21: =SUMIFS(ar6_r10!$F$2:$F$999,ar6_r10!$A$2:$A$999,Veda!$E$5,ar6_r10!$C$2:$C$999,Veda!N$17,ar6_r10!$M$2:$M$999,Veda!$G21) -> 0.06 | O21: =SUMIFS(ar6_r10!$F$2:$F$999,ar6_r10!$A$2:$A$999,Veda!$E$5,ar6_r10!$C$2:$C$999,Veda!O$17,ar6_r10!$M$2:$M$999,Veda!$G21) -> 0.08 | S21: elc_transport | T21: =I21*T$14 -> 1.8591 | U21: =T21 -> 1.8591 | V21: =U21 -> 1.8591 | W21: =V21 -> 1.8591 | X21: =W21 -> 1.8591 | Y21: =X21 -> 1.8591 | Z21: =Y21 -> 1.8591 | AA21: demand | AC21: non-road transport demand assumed to be constant | AJ21: =AJ16+1 -> 3
A22: 5 | B22: =VLOOKUP(E22,$AK$9:$AL$15,2,FALSE)&"."&VLOOKUP(D22,$AH$9:$AI$24,2,FALSE) -> b 2 deg (50%).ts_012 | C22: =C21+1 -> 14 | D22: =VLOOKUP(AJ22,$AG$9:$AH$22,2,FALSE) -> ts_012 | E22: =E17 -> C4 | S22: elc_roadtransport | T22: =T14-SUM(T19:T21) -> 0 | U22: =U14-SUM(U19:U21) -> 2.454012 | V22: =V14-SUM(V19:V21) -> 5.447163 | W22: =W14-SUM(W19:W21) -> 12.08415 | X22: =X14-SUM(X19:X21) -> 20.524464 | Y22: =Y14-SUM(Y19:Y21) -> 25.860081 | Z22: =Z14-SUM(Z19:Z21) -> 54.136992 | AA22: demand | AJ22: =AJ17+1 -> 3
A23: 5 | B23: =VLOOKUP(E23,$AK$9:$AL$15,2,FALSE)&"."&VLOOKUP(D23,$AH$9:$AI$24,2,FALSE) -> a 3 deg.ts_012 | C23: =C22+1 -> 15 | D23: =VLOOKUP(AJ23,$AG$9:$AH$22,2,FALSE) -> ts_012 | E23: =E18 -> C7 | S23: * | AJ23: =AJ18+1 -> 3
A24: 5 | B24: =VLOOKUP(E24,$AK$9:$AL$15,2,FALSE)&"."&VLOOKUP(D24,$AH$9:$AI$24,2,FALSE) -> e 1.5 deg no OS.ts_030 | C24: =C23+1 -> 16 | D24: =VLOOKUP(AJ24,$AG$9:$AH$22,2,FALSE) -> ts_030 | E24: =E19 -> C1 | G24: CO2 price | I24: 0 | J24: 0 | K24: =SUMIFS(ar6_r10!$F$2:$F$999,ar6_r10!$A$2:$A$999,Veda!$E$5,ar6_r10!$C$2:$C$999,Veda!K$17,ar6_r10!$M$2:$M$999,Veda!$G24) -> 55.79 | L24: =SUMIFS(ar6_r10!$F$2:$F$999,ar6_r10!$A$2:$A$999,Veda!$E$5,ar6_r10!$C$2:$C$999,Veda!L$17,ar6_r10!$M$2:$M$999,Veda!$G24) -> 89.54 | M24: =SUMIFS(ar6_r10!$F$2:$F$999,ar6_r10!$A$2:$A$999,Veda!$E$5,ar6_r10!$C$2:$C$999,Veda!M$17,ar6_r10!$M$2:$M$999,Veda!$G24) -> 128.23 | N24: =SUMIFS(ar6_r10!$F$2:$F$999,ar6_r10!$A$2:$A$999,Veda!$E$5,ar6_r10!$C$2:$C$999,Veda!N$17,ar6_r10!$M$2:$M$999,Veda!$G24) -> 171.82 | O24: =SUMIFS(ar6_r10!$F$2:$F$999,ar6_r10!$A$2:$A$999,Veda!$E$5,ar6_r10!$C$2:$C$999,Veda!O$17,ar6_r10!$M$2:$M$999,Veda!$G24) -> 208.87 | S24: co2net | U24: 0 | V24: =K24/1000 -> 0.05579 | W24: =L24/1000 -> 0.08954 | X24: =M24/1000 -> 0.12823 | Y24: =N24/1000 -> 0.17182 | Z24: =O24/1000 -> 0.20887 | AA24: com_taxnet | AJ24: =AJ19+1 -> 4
A25: 5 | B25: =VLOOKUP(E25,$AK$9:$AL$15,2,FALSE)&"."&VLOOKUP(D25,$AH$9:$AI$24,2,FALSE) -> d 1.5 deg OS.ts_030 | C25: =C24+1 -> 17 | D25: =VLOOKUP(AJ25,$AG$9:$AH$22,2,FALSE) -> ts_030 | E25: =E20 -> C2 | AJ25: =AJ20+1 -> 4
A26: 5 | B26: =VLOOKUP(E26,$AK$9:$AL$15,2,FALSE)&"."&VLOOKUP(D26,$AH$9:$AI$24,2,FALSE) -> c 2 deg (67%).ts_030 | C26: =C25+1 -> 18 | D26: =VLOOKUP(AJ26,$AG$9:$AH$22,2,FALSE) -> ts_030 | E26: =E21 -> C3 | S26: ~TFM_INS-TS | AJ26: =AJ21+1 -> 4
A27: 5 | B27: =VLOOKUP(E27,$AK$9:$AL$15,2,FALSE)&"."&VLOOKUP(D27,$AH$9:$AI$24,2,FALSE) -> b 2 deg (50%).ts_030 | C27: =C26+1 -> 19 | D27: =VLOOKUP(AJ27,$AG$9:$AH$22,2,FALSE) -> ts_030 | E27: =E22 -> C4 | S27: process | T27: =T17 -> 2022 | U27: =U17 -> 2025 | V27: =V17 -> 2030 | W27: =W17 -> 2035 | X27: =X17 -> 2040 | Y27: =Y17 -> 2045 | Z27: =Z17 -> 2050 | AA27: attribute | AB27: limtype | AJ27: =AJ22+1 -> 4
A28: 5 | B28: =VLOOKUP(E28,$AK$9:$AL$15,2,FALSE)&"."&VLOOKUP(D28,$AH$9:$AI$24,2,FALSE) -> a 3 deg.ts_030 | C28: =C27+1 -> 20 | D28: =VLOOKUP(AJ28,$AG$9:$AH$22,2,FALSE) -> ts_030 | E28: =E23 -> C7 | Q28: =SUMIFS(iea_data!G3:G9999,iea_data!$B$3:$B$9999,Veda!$S$11) -> 0.03 | S28: Trd_electricity import | T28: =Q28 -> 0.03 | AA28: ACT_BND | AB28: FX | AJ28: =AJ23+1 -> 4
A29: 5 | B29: =VLOOKUP(E29,$AK$9:$AL$15,2,FALSE)&"."&VLOOKUP(D29,$AH$9:$AI$24,2,FALSE) -> e 1.5 deg no OS.ts_048 | C29: =C28+1 -> 21 | D29: =VLOOKUP(AJ29,$AG$9:$AH$22,2,FALSE) -> ts_048 | E29: =E24 -> C1 | Q29: =SUMIFS(iea_data!H3:H9999,iea_data!$B$3:$B$9999,Veda!$S$11) -> -1.42 | S29: Trd_electricity export | T29: =-1*Q29 -> 1.42 | AA29: ACT_BND | AB29: FX | AJ29: =AJ24+1 -> 5
A30: 5 | B30: =VLOOKUP(E30,$AK$9:$AL$15,2,FALSE)&"."&VLOOKUP(D30,$AH$9:$AI$24,2,FALSE) -> d 1.5 deg OS.ts_048 | C30: =C29+1 -> 22 | D30: =VLOOKUP(AJ30,$AG$9:$AH$22,2,FALSE) -> ts_048 | E30: =E25 -> C2 | AJ30: =AJ25+1 -> 5
A31: 5 | B31: =VLOOKUP(E31,$AK$9:$AL$15,2,FALSE)&"."&VLOOKUP(D31,$AH$9:$AI$24,2,FALSE) -> c 2 deg (67%).ts_048 | C31: =C30+1 -> 23 | D31: =VLOOKUP(AJ31,$AG$9:$AH$22,2,FALSE) -> ts_048 | E31: =E26 -> C3 | AJ31: =AJ26+1 -> 5
A32: 5 | B32: =VLOOKUP(E32,$AK$9:$AL$15,2,FALSE)&"."&VLOOKUP(D32,$AH$9:$AI$24,2,FALSE) -> b 2 deg (50%).ts_048 | C32: =C31+1 -> 24 | D32: =VLOOKUP(AJ32,$AG$9:$AH$22,2,FALSE) -> ts_048 | E32: =E27 -> C4 | AJ32: =AJ27+1 -> 5
A33: 5 | B33: =VLOOKUP(E33,$AK$9:$AL$15,2,FALSE)&"."&VLOOKUP(D33,$AH$9:$AI$24,2,FALSE) -> a 3 deg.ts_048 | C33: =C32+1 -> 25 | D33: =VLOOKUP(AJ33,$AG$9:$AH$22,2,FALSE) -> ts_048 | E33: =E28 -> C7 | AJ33: =AJ28+1 -> 5
A34: 5 | B34: =VLOOKUP(E34,$AK$9:$AL$15,2,FALSE)&"."&VLOOKUP(D34,$AH$9:$AI$24,2,FALSE) -> e 1.5 deg no OS.ts_072 | C34: =C33+1 -> 26 | D34: =VLOOKUP(AJ34,$AG$9:$AH$22,2,FALSE) -> ts_072 | E34: =E29 -> C1 | AJ34: =AJ29+1 -> 6
A35: 5 | B35: =VLOOKUP(E35,$AK$9:$AL$15,2,FALSE)&"."&VLOOKUP(D35,$AH$9:$AI$24,2,FALSE) -> d 1.5 deg OS.ts_072 | C35: =C34+1 -> 27 | D35: =VLOOKUP(AJ35,$AG$9:$AH$22,2,FALSE) -> ts_072 | E35: =E30 -> C2 | AJ35: =AJ30+1 -> 6
A36: 5 | B36: =VLOOKUP(E36,$AK$9:$AL$15,2,FALSE)&"."&VLOOKUP(D36,$AH$9:$AI$24,2,FALSE) -> c 2 deg (67%).ts_072 | C36: =C35+1 -> 28 | D36: =VLOOKUP(AJ36,$AG$9:$AH$22,2,FALSE) -> ts_072 | E36: =E31 -> C3 | G36: C7 | AJ36: =AJ31+1 -> 6
A37: 5 | B37: =VLOOKUP(E37,$AK$9:$AL$15,2,FALSE)&"."&VLOOKUP(D37,$AH$9:$AI$24,2,FALSE) -> b 2 deg (50%).ts_072 | C37: =C36+1 -> 29 | D37: =VLOOKUP(AJ37,$AG$9:$AH$22,2,FALSE) -> ts_072 | E37: =E32 -> C4 | G37: Gas Price | I37: =SUMIFS(ar6_r10!$F$2:$F$999,ar6_r10!$A$2:$A$999,Veda!$G$36,ar6_r10!$C$2:$C$999,Veda!I$17,ar6_r10!$M$2:$M$999,Veda!$G37) -> 1 | J37: =SUMIFS(ar6_r10!$F$2:$F$999,ar6_r10!$A$2:$A$999,Veda!$G$36,ar6_r10!$C$2:$C$999,Veda!J$17,ar6_r10!$M$2:$M$999,Veda!$G37) -> 1.08 | K37: =SUMIFS(ar6_r10!$F$2:$F$999,ar6_r10!$A$2:$A$999,Veda!$G$36,ar6_r10!$C$2:$C$999,Veda!K$17,ar6_r10!$M$2:$M$999,Veda!$G37) -> 1.29 | L37: =SUMIFS(ar6_r10!$F$2:$F$999,ar6_r10!$A$2:$A$999,Veda!$G$36,ar6_r10!$C$2:$C$999,Veda!L$17,ar6_r10!$M$2:$M$999,Veda!$G37) -> 1.28 | M37: =SUMIFS(ar6_r10!$F$2:$F$999,ar6_r10!$A$2:$A$999,Veda!$G$36,ar6_r10!$C$2:$C$999,Veda!M$17,ar6_r10!$M$2:$M$999,Veda!$G37) -> 1.4 | N37: =SUMIFS(ar6_r10!$F$2:$F$999,ar6_r10!$A$2:$A$999,Veda!$G$36,ar6_r10!$C$2:$C$999,Veda!N$17,ar6_r10!$M$2:$M$999,Veda!$G37) -> 1.48 | O37: =SUMIFS(ar6_r10!$F$2:$F$999,ar6_r10!$A$2:$A$999,Veda!$G$36,ar6_r10!$C$2:$C$999,Veda!O$17,ar6_r10!$M$2:$M$999,Veda!$G37) -> 1.53 | AJ37: =AJ32+1 -> 6
A38: 5 | B38: =VLOOKUP(E38,$AK$9:$AL$15,2,FALSE)&"."&VLOOKUP(D38,$AH$9:$AI$24,2,FALSE) -> a 3 deg.ts_072 | C38: =C37+1 -> 30 | D38: =VLOOKUP(AJ38,$AG$9:$AH$22,2,FALSE) -> ts_072 | E38: =E33 -> C7 | G38: Coal Price | I38: =SUMIFS(ar6_r10!$F$2:$F$999,ar6_r10!$A$2:$A$999,Veda!$G$36,ar6_r10!$C$2:$C$999,Veda!I$17,ar6_r10!$M$2:$M$999,Veda!$G38) -> 1 | J38: =SUMIFS(ar6_r10!$F$2:$F$999,ar6_r10!$A$2:$A$999,Veda!$G$36,ar6_r10!$C$2:$C$999,Veda!J$17,ar6_r10!$M$2:$M$999,Veda!$G38) -> 1.04 | K38: =SUMIFS(ar6_r10!$F$2:$F$999,ar6_r10!$A$2:$A$999,Veda!$G$36,ar6_r10!$C$2:$C$999,Veda!K$17,ar6_r10!$M$2:$M$999,Veda!$G38) -> 1.11 | L38: =SUMIFS(ar6_r10!$F$2:$F$999,ar6_r10!$A$2:$A$999,Veda!$G$36,ar6_r10!$C$2:$C$999,Veda!L$17,ar6_r10!$M$2:$M$999,Veda!$G38) -> 1.14 | M38: =SUMIFS(ar6_r10!$F$2:$F$999,ar6_r10!$A$2:$A$999,Veda!$G$36,ar6_r10!$C$2:$C$999,Veda!M$17,ar6_r10!$M$2:$M$999,Veda!$G38) -> 1.16 | N38: =SUMIFS(ar6_r10!$F$2:$F$999,ar6_r10!$A$2:$A$999,Veda!$G$36,ar6_r10!$C$2:$C$999,Veda!N$17,ar6_r10!$M$2:$M$999,Veda!$G38) -> 1.18 | O38: =SUMIFS(ar6_r10!$F$2:$F$999,ar6_r10!$A$2:$A$999,Veda!$G$36,ar6_r10!$C$2:$C$999,Veda!O$17,ar6_r10!$M$2:$M$999,Veda!$G38) -> 1.19 | AJ38: =AJ33+1 -> 6
A39: 5 | B39: =VLOOKUP(E39,$AK$9:$AL$15,2,FALSE)&"."&VLOOKUP(D39,$AH$9:$AI$24,2,FALSE) -> e 1.5 deg no OS.ts_144 | C39: =C38+1 -> 31 | D39: =VLOOKUP(AJ39,$AG$9:$AH$22,2,FALSE) -> ts_144 | E39: =E34 -> C1 | G39: Oil Price | I39: =SUMIFS(ar6_r10!$F$2:$F$999,ar6_r10!$A$2:$A$999,Veda!$G$36,ar6_r10!$C$2:$C$999,Veda!I$17,ar6_r10!$M$2:$M$999,Veda!$G39) -> 1 | J39: =SUMIFS(ar6_r10!$F$2:$F$999,ar6_r10!$A$2:$A$999,Veda!$G$36,ar6_r10!$C$2:$C$999,Veda!J$17,ar6_r10!$M$2:$M$999,Veda!$G39) -> 1.17 | K39: =SUMIFS(ar6_r10!$F$2:$F$999,ar6_r10!$A$2:$A$999,Veda!$G$36,ar6_r10!$C$2:$C$999,Veda!K$17,ar6_r10!$M$2:$M$999,Veda!$G39) -> 1.34 | L39: =SUMIFS(ar6_r10!$F$2:$F$999,ar6_r10!$A$2:$A$999,Veda!$G$36,ar6_r10!$C$2:$C$999,Veda!L$17,ar6_r10!$M$2:$M$999,Veda!$G39) -> 1.33 | M39: =SUMIFS(ar6_r10!$F$2:$F$999,ar6_r10!$A$2:$A$999,Veda!$G$36,ar6_r10!$C$2:$C$999,Veda!M$17,ar6_r10!$M$2:$M$999,Veda!$G39) -> 1.44 | N39: =SUMIFS(ar6_r10!$F$2:$F$999,ar6_r10!$A$2:$A$999,Veda!$G$36,ar6_r10!$C$2:$C$999,Veda!N$17,ar6_r10!$M$2:$M$999,Veda!$G39) -> 1.63 | O39: =SUMIFS(ar6_r10!$F$2:$F$999,ar6_r10!$A$2:$A$999,Veda!$G$36,ar6_r10!$C$2:$C$999,Veda!O$17,ar6_r10!$M$2:$M$999,Veda!$G39) -> 1.89 | AJ39: =AJ34+1 -> 7
A40: 5 | B40: =VLOOKUP(E40,$AK$9:$AL$15,2,FALSE)&"."&VLOOKUP(D40,$AH$9:$AI$24,2,FALSE) -> d 1.5 deg OS.ts_144 | C40: =C39+1 -> 32 | D40: =VLOOKUP(AJ40,$AG$9:$AH$22,2,FALSE) -> ts_144 | E40: =E35 -> C2 | G40: Biomass Price | I40: =SUMIFS(ar6_r10!$F$2:$F$999,ar6_r10!$A$2:$A$999,Veda!$G$36,ar6_r10!$C$2:$C$999,Veda!I$17,ar6_r10!$M$2:$M$999,Veda!$G40) -> 1 | J40: =SUMIFS(ar6_r10!$F$2:$F$999,ar6_r10!$A$2:$A$999,Veda!$G$36,ar6_r10!$C$2:$C$999,Veda!J$17,ar6_r10!$M$2:$M$999,Veda!$G40) -> 0.97 | K40: =SUMIFS(ar6_r10!$F$2:$F$999,ar6_r10!$A$2:$A$999,Veda!$G$36,ar6_r10!$C$2:$C$999,Veda!K$17,ar6_r10!$M$2:$M$999,Veda!$G40) -> 0.95 | L40: =SUMIFS(ar6_r10!$F$2:$F$999,ar6_r10!$A$2:$A$999,Veda!$G$36,ar6_r10!$C$2:$C$999,Veda!L$17,ar6_r10!$M$2:$M$999,Veda!$G40) -> 0.93 | M40: =SUMIFS(ar6_r10!$F$2:$F$999,ar6_r10!$A$2:$A$999,Veda!$G$36,ar6_r10!$C$2:$C$999,Veda!M$17,ar6_r10!$M$2:$M$999,Veda!$G40) -> 0.89 | N40: =SUMIFS(ar6_r10!$F$2:$F$999,ar6_r10!$A$2:$A$999,Veda!$G$36,ar6_r10!$C$2:$C$999,Veda!N$17,ar6_r10!$M$2:$M$999,Veda!$G40) -> 0.88 | O40: =SUMIFS(ar6_r10!$F$2:$F$999,ar6_r10!$A$2:$A$999,Veda!$G$36,ar6_r10!$C$2:$C$999,Veda!O$17,ar6_r10!$M$2:$M$999,Veda!$G40) -> 0.95 | AJ40: =AJ35+1 -> 7
A41: 5 | B41: =VLOOKUP(E41,$AK$9:$AL$15,2,FALSE)&"."&VLOOKUP(D41,$AH$9:$AI$24,2,FALSE) -> c 2 deg (67%).ts_144 | C41: =C40+1 -> 33 | D41: =VLOOKUP(AJ41,$AG$9:$AH$22,2,FALSE) -> ts_144 | E41: =E36 -> C3 | AJ41: =AJ36+1 -> 7
A42: 5 | B42: =VLOOKUP(E42,$AK$9:$AL$15,2,FALSE)&"."&VLOOKUP(D42,$AH$9:$AI$24,2,FALSE) -> b 2 deg (50%).ts_144 | C42: =C41+1 -> 34 | D42: =VLOOKUP(AJ42,$AG$9:$AH$22,2,FALSE) -> ts_144 | E42: =E37 -> C4 | AJ42: =AJ37+1 -> 7
...

Sheet fuel_prices
A9: Fuel Prices
A10: iso | B10: gas_low | C10: gas_high | D10: coal_low | E10: coal_high | F10: oil_low | G10: oil_high | H10: bioenergy_low | I10: bioenergy_high | J10: Notes
A11: MYS | B11: 17.1 | C11: 27.4 | D11: 11 | E11: 15.2 | F11: 42 | G11: 52 | H11: 12 | I11: 20 | J11: Domestic gas production, palm residues

Sheet iea_data
A9: IEA Baseline Data
A10: iso | B10: year | C10: industry_twh | D10: buildings_agri_twh | E10: nonroad_transport_twh | F10: road_transport_twh | G10: imports_twh | H10: exports_twh | I10: total_production_twh
A11: MYS | B11: 2000 | C11: 40.93 | D11: 28.53 | E11: 0.05 | F11: 0 | G11: 0 | H11: 0 | I11: 69.26
A12: MYS | B12: 2001 | C12: 42.61 | D12: 30.94 | E12: 0.04 | F12: 0 | G12: 0 | H12: 0 | I12: 71.08
A13: MYS | B13: 2002 | C13: 44.48 | D13: 33.25 | E13: 0.05 | F13: 0 | G13: 0 | H13: -0.03 | I13: 74.25
A14: MYS | B14: 2003 | C14: 47.12 | D14: 35.66 | E14: 0.06 | F14: 0 | G14: 0 | H14: -0.2 | I14: 78.47
A15: MYS | B15: 2004 | C15: 48.72 | D15: 38.35 | E15: 0.05 | F15: 0 | G15: 0.1 | H15: -0.62 | I15: 82.28
A16: MYS | B16: 2005 | C16: 49.12 | D16: 41.49 | E16: 0.06 | F16: 0 | G16: 0 | H16: -2.23 | I16: 82.67
A17: MYS | B17: 2006 | C17: 51.19 | D17: 44.1 | E17: 0.06 | F17: 0 | G17: 0 | H17: -2.32 | I17: 89.83
A18: MYS | B18: 2007 | C18: 53.41 | D18: 47.6 | E18: 0.04 | F18: 0 | G18: 0 | H18: -2.26 | I18: 97.52
A19: MYS | B19: 2008 | C19: 54.61 | D19: 49.83 | E19: 0.17 | F19: 0 | G19: 0.11 | H19: -0.58 | I19: 97.8
A20: MYS | B20: 2009 | C20: 62.79 | D20: 52.98 | E20: 0.14 | F20: 0 | G20: 0.01 | H20: -0.1 | I20: 116
A21: MYS | B21: 2010 | C21: 66.5 | D21: 57.93 | E21: 0.21 | F21: 0 | G21: 0 | H21: -0.15 | I21: 124.79
A22: MYS | B22: 2011 | C22: 69.4 | D22: 60.03 | E22: 0.21 | F22: 0 | G22: 0.37 | H22: -0.01 | I22: 129.28
... A33: MYS | B33: 2022 | C33: 99.43 | D33: 83.83 | E33: 0.25 | F33: 0 | G33: 0.03 | H33: -1.42 | I33: 187.3

Sheet ar6_r10
A9: AR6 Scenario Drivers
A10: Category | B10: Region | C10: Year | D10: count | E10: mean | F10: median | G10: std | H10: min | I10: max | J10: q25 | K10: q75 | L10: category_description | M10: attribute
A11: C1 | B11: R10REST_ASIA | C11: 2020 | D11: 60 | E11: 3.28 | F11: 0.55 | G11: 3.92 | H11: 0 | I11: 9.19 | J11: 0 | K11: 8.05 | L11: Limit warming to 1.5°C (>50%) with no or limited overshoot | M11: CO2 price
A12: C1 | B12: R10REST_ASIA | C12: 2025 | D12: 60 | E12: 144.21 | F12: 117.22 | G12: 125.47 | H12: 9.49 | I12: 626.48 | J12: 72.92 | K12: 177.75 | L12: Limit warming to 1.5°C (>50%) with no or limited overshoot | M12: CO2 price
A13: C1 | B13: R10REST_ASIA | C13: 2030 | D13: 60 | E13: 204.31 | F13: 186.64 | G13: 116.81 | H13: 6.28 | I13: 673.46 | J13: 116.89 | K13: 241.69 | L13: Limit warming to 1.5°C (>50%) with no or limited overshoot | M13: CO2 price
A14: C1 | B14: R10REST_ASIA | C14: 2035 | D14: 60 | E14: 292.3 | F14: 250.8 | G14: 154.01 | H14: 34.16 | I14: 859.53 | J14: 184.18 | K14: 361.62 | L14: Limit warming to 1.5°C (>50%) with no or limited overshoot | M14: CO2 price
A15: C1 | B15: R10REST_ASIA | C15: 2040 | D15: 60 | E15: 406.37 | F15: 325.37 | G15: 208.03 | H15: 145.16 | I15: 1097.01 | J15: 278.29 | K15: 499.12 | L15: Limit warming to 1.5°C (>50%) with no or limited overshoot | M15: CO2 price
A16: C1 | B16: R10REST_ASIA | C16: 2045 | D16: 60 | E16: 524.62 | F16: 440.67 | G16: 244.73 | H16: 193.42 | I16: 1269.88 | J16: 355.81 | K16: 713.93 | L16: Limit warming to 1.5°C (>50%) with no or limited overshoot | M16: CO2 price
A17: C1 | B17: R10REST_ASIA | C17: 2050 | D17: 60 | E17: 628.96 | F17: 581.75 | G17: 257.45 | H17: 209.76 | I17: 1170.26 | J17: 412.98 | K17: 808.29 | L17: Limit warming to 1.5°C (>50%) with no or limited overshoot | M17: CO2 price
A18: C2 | B18: R10REST_ASIA | C18: 2020 | D18: 86 | E18: 1.62 | F18: 0.12 | G18: 2.95 | H18: 0 | I18: 9.08 | J18: 0 | K18: 0.88 | L18: Limit warming to 1.5°C (>67%) with high overshoot | M18: CO2 price
A19: C2 | B19: R10REST_ASIA | C19: 2025 | D19: 75 | E19: 46.43 | F19: 28.76 | G19: 40.02 | H19: 7.08 | I19: 174.97 | J19: 20.12 | K19: 61.53 | L19: Limit warming to 1.5°C (>67%) with high overshoot | M19: CO2 price
A20: C2 | B20: R10REST_ASIA | C20: 2030 | D20: 86 | E20: 62.15 | F20: 50 | G20: 46.76 | H20: 0 | I20: 221.93 | J20: 25.96 | K20: 72.46 | L20: Limit warming to 1.5°C (>67%) with high overshoot | M20: CO2 price
A21: C2 | B21: R10REST_ASIA | C21: 2035 | D21: 75 | E21: 199.95 | F21: 135.74 | G21: 294.3 | H21: 46.61 | I21: 2037.12 | J21: 86.12 | K21: 201.85 | L21: Limit warming to 1.5°C (>67%) with high overshoot | M21: CO2 price
A22: C2 | B22: R10REST_ASIA | C22: 2040 | D22: 86 | E22: 246.92 | F22: 165.64 | G22: 360.4 | H22: 0 | I22: 2600 | J22: 111.3 | K22: 257.19 | L22: Limit warming to 1.5°C (>67%) with high overshoot | M22: CO2 price
... A360: C7 | B360: R10REST_ASIA | C360: 2050 | D360: 7 | E360: 1.06 | F360: 0.95 | G360: 0.3 | H360: 0.86 | I360: 1.7 | J360: 0.87 | K360: 1.1 | L360: Likely above 3°C warming with limited mitigation | M360: Biomass price

Sheet ev_charging_uc
A10: =IFERROR(Veda!D5,"ts_12t") -> ts_annual | C10: day_night | D10: ts_012 | F10: day_night | G10: ts_024 | I10: day_night | J10: ts_036 | L10: day_night | M10: ts_048 | O10: day_night | P10: ts_144 | R10: day_night | S10: ts_288 | U10: day_night | V10: ts_072P10 | X10: day_night | Y10: ts_072P90 | AA10: day_night | AB10: ts_annual | AD10: day_night | AE10: ts_12t
C11: D | D11: S04aH03,S04aH02,S01aH02,S01aH03,S03aH02,S02aH02,S03aH03,S02aH03 | F11: D | G11: S03aH03,S01aH05,S03aH04,S02aH03,S04aH03,S02aH02,S04aH02,S03aH02,S04aH05,S01aH04,S02aH04,S02aH05,S01aH02,S04aH04,S03aH05,S01aH03 | I11: D | J11: S02aH02,S02aH03,S03aH05,S05aH05,S06aH04,S04aH03,S03aH02,S01aH05,S06aH05,S02aH04,S02aH05,S01aH03,S05aH02,S05aH03,S05aH04,S06aH02,S06aH03,S03aH04,S04aH02,S01aH02,S04aH04,S01aH04,S03aH03,S04aH05 | L11: D | M11: S03aH02,S01aH06,S02aH03,S05aH07,S04aH05,S02aH02,S06aH06,S01aH02,S04aH04,S04aH02,S02aH06,S03aH05,S04aH07,S05aH05,S06aH04,S02aH04,S02aH05,S06aH07,S04aH03,S03aH03,S03aH04,S01aH04,S01aH07,S02aH07,S01aH03,S05aH02,S05aH03,S05aH06,S04aH06,S05aH04,S06aH02,S06aH03,S01aH05,S03aH06,S03aH07,S06aH05 | O11: D | P11: S01aH04,S01aH07,S02aH07,S02aH09,S04aH09,S04aH11,S07aH02,S07aH06,S08aH09,S03aH11,S04aH03,S07aH04,S07aH09,S08aH03,S09aH04,S04aH02,S05aH11,S08aH07,S09aH02,S09aH03,S01aH05,S01aH08,S02aH08,S03aH06,S03aH07,S06aH05,S08aH10,S02aH04,S02aH05,S03aH09,S05aH09,S06aH07,S07aH07,S07aH08,S08aH08,S01aH06,S02aH03,S05aH07,S06aH09,S06aH11,S07aH03,S07aH11,S08aH06,S09aH09,S09aH10,S05aH08,S08aH02,S09aH06,S02aH06,S03aH05,S03aH08,S03aH10,S04aH07,S05aH05,S06aH04,S06aH08,S08aH04,S01aH11,S02aH02,S04aH10,S06aH06,S06aH10,S03aH03,S09aH05,S01aH10,S02aH11,S03aH02,S07aH05,S07aH10,S08aH11,S01aH02,S04aH04,S05aH10,S09aH11,S01aH09,S03aH04,S08aH05,S09aH07,S01aH03,S02aH10,S05aH02,S05aH03,S05aH06,S04aH06,S05aH04,S06aH02,S06aH03,S09aH08,S04aH05,S04aH08 | R11: D | S11: S03aH11,S04aH03,S07aH04,S07aH09,S08aH03,S09aH04,S11aH07,S12aH02,S14aH06,S01aH10,S02aH11,S03aH02,S07aH05,S07aH10,S08aH11,S11aH11,S14aH02,S14aH10,S01aH09,S03aH04,S08aH05,S09aH07,S10aH09,S10aH10,S11aH05,S11aH10,S12aH03,S01aH06,S02aH03,S05aH07,S06aH09,S06aH11,S07aH03,S07aH11,S08aH06,S09aH09,S09aH10,S10aH07,S12aH10,S13aH09,S13aH10,S05aH08,S08aH02,S09aH06,S10aH08,S14aH07,S01aH03,S02aH10,S05aH02,S05aH03,S05aH06,S12aH09,S04aH05,S04aH08,S11aH09,S12aH08,S13aH04,S13aH08,S01aH04,S01aH07,S02aH07,S02aH09,S04aH09,S04aH11,S07aH02,S07aH06,S08aH09,S10aH11,S13aH07,S02aH04,S02aH05,S03aH09,S05aH09,S06aH07,S07aH07,S07aH08,S08aH08,S10aH03,S10aH05,S04aH02,S05aH11,S08aH07,S09aH02,S09aH03,S11aH03,S11aH04,S12aH11,S14aH03,S01aH02,S04aH04,S05aH10,S09aH11,S13aH11,S14aH08,S01aH11,S02aH02,S04aH10,S06aH06,S06aH10,S11aH08,S14aH04,S14aH05,S03aH03,S09aH05,S12aH07,S13aH05,S04aH06,S05aH04,S06aH02,S06aH03,S09aH08,S10aH04,S12aH06,S13aH06,S14aH09,S14aH11,S01aH05,S01aH08,S02aH08,S03aH06,S03aH07,S06aH05,S08aH10,S10aH02,S10aH06,S11aH06,S12aH04,S12aH05,S02aH06,S03aH05,S03aH08,S03aH10,S04aH07,S05aH05,S06aH04,S06aH08,S08aH04,S11aH02,S13aH02,S13aH03 | U11: D | V11: S01aH02,S04aH04,S01aH03,S05aH02,S05aH03,S03aH04,S08aH05,S03aH03,S09aH05,S08aH02,S04aH03,S07aH04,S08aH03,S09aH04,S02aH04,S02aH05,S02aH03,S07aH03,S01aH04,S07aH02,S04aH02,S09aH02,S09aH03,S04aH05,S02aH02,S03aH02,S07aH05,S01aH05,S06aH05,S03aH05,S05aH05,S06aH04,S08aH04,S05aH04,S06aH02,S06aH03 | X11: D | Y11: S02aH04,S02aH05,S04aH02,S09aH02,S09aH03,S08aH02,S01aH04,S07aH02,S04aH03,S07aH04,S08aH03,S09aH04,S02aH03,S07aH03,S01aH02,S04aH04,S03aH05,S05aH05,S06aH04,S08aH04,S02aH02,S03aH03,S09aH05,S05aH04,S06aH02,S06aH03,S04aH05,S03aH04,S08aH05,S01aH03,S05aH02,S05aH03,S03aH02,S07aH05,S01aH05,S06aH05 | AA11: D | AB11: AllSaAllH | AD11: D | AE11: FaP,SaP,RaD,WaP,SaD,RaP,WaD,FaD
C12: N | D12: S02aH01,S03aH01,S01aH01,S04aH01 | F12: N | G12: S01aH01,S04aH01,S04aH06,S02aH01,S03aH01,S01aH06,S02aH06,S03aH06 | I12: N | J12: S03aH01,S01aH01,S04aH01,S04aH06,S06aH01,S02aH01,S05aH06,S02aH06,S01aH06,S05aH01,S03aH06,S06aH06 | L12: N | M12: S01aH01,S04aH01,S05aH08,S03aH01,S01aH08,S02aH08,S03aH08,S06aH08,S02aH01,S04aH08,S06aH01,S05aH01 | O12: N | P12: S08aH01,S02aH01,S04aH12,S06aH12,S01aH01,S02aH12,S04aH01,S06aH01,S07aH12,S03aH01,S08aH12,S03aH12,S05aH01,S05aH12,S09aH01,S01aH12,S07aH01,S09aH12 | R12: N | S12: S02aH01,S05aH01,S05aH12,S01aH01,S02aH12,S04aH01,S11aH01,S06aH01,S07aH12,S14aH01,S09aH01,S13aH01,S09aH12,S08aH01,S10aH01,S06aH12,S12aH01,S04aH12,S10aH12,S11aH12,S03aH12,S03aH01,S08aH12,S12aH12,S01aH12,S07aH01,S13aH12,S14aH12 | U12: N | V12: S03aH06,S09aH01,S05aH01,S07aH06,S06aH06,S06aH01,S02aH01,S05aH06,S02aH06,S01aH01,S04aH01,S04aH06,S08aH01,S09aH06,S03aH01,S01aH06,S07aH01,S08aH06 | X12: N | Y12: S02aH06,S06aH01,S08aH01,S02aH01,S05aH06,S01aH01,S04aH01,S04aH06,S03aH06,S03aH01,S06aH06,S01aH06,S07aH01,S08aH06,S09aH06,S05aH01,S07aH06,S09aH01 | AA12: N | AB12: AllSaAllH | AD12: N | AE12: RaN,FaP,SaP,FaN,SaN,WaN,RaP,WaP
I17: 0.75 | K17: share of charging at night
C18: ~UC_Sets: R_E: AllRegions
H21: =IF(H23=H24,"Not Required!","~UC_T: LO") -> Not Required!
C22: UC_N | D22: Pset_CI | E22: Pset_CO | F22: pset_pn | G22: Cset_CN | H22: TimeSlice | I22: UC_FLO | J22: UC_RHSRT | K22: UC_RHSRT~0
C23: UC_bev night chg limit | D23: ELC | E23: =G23 -> AuxStoIN | F23: *EV* | G23: AuxStoIN | H23: =HLOOKUP($A$10,$D$10:$CU$12,3,FALSE) -> AllSaAllH | I23: =1+I24 -> 0.25 | J23: 0 | K23: 3 | M23: night
D24: ELC | E24: =G24 -> AuxStoIN | F24: *EV* | G24: AuxStoIN | H24: =HLOOKUP($A$10,$D$10:$CU$12,2,FALSE) -> AllSaAllH | I24: =-$I$17 -> -0.75 | M24: day

Sheet ts_012
C9: =IF(A11="x","DeActivated","~TimeSlices") -> DeActivated | I9: =IF(A11="x","DeActivated","~TFM_DINS-AT") -> DeActivated | N9: =IF(A11="x","DeActivated","~TFM_DINS-AT") -> DeActivated | S9: =IF(A11="x","DeActivated","~TFM_DINS-AT") -> DeActivated | X9: =IF(A11="x","DeActivated","~TFM_DINS-AT") -> DeActivated | AC9: =IF(A11="x","DeActivated","~TFM_DINS-AT") -> DeActivated | AG9: =IF(A11="x","DeActivated","~TFM_DINS-AT") -> DeActivated | AK9: =IF(A11="x","DeActivated","~TFM_INS-AT") -> DeActivated
A10: ts_012 | C10: season | D10: weekly | E10: daynite | F10: wparent | G10: dparent | I10: commodity | J10: timeslice | K10: com_fr | L10: process | N10: commodity | O10: timeslice | P10: com_fr | Q10: process | S10: commodity | T10: timeslice | U10: com_fr | V10: process | X10: g_yrfr | Y10: com_fr | Z10: timeslice | AA10: commodity | AC10: commodity | AD10: timeslice | AE10: com_fr | AG10: commodity | AH10: timeslice | AI10: com_pkflx | AK10: Year | AL10: timeslice | AM10: ncap_afs | AN10: pset_ci
A11: =IFERROR(IF(Veda!D5=A10,"ok","x"),"") -> x | C11: S01 | D11: a | E11: H01 | F11: S01,S02,S03,S04 | G11: a | I11: elc_spv_MYS_001 | J11: S01aH01 | K11: 0.0063895928 | L11: IMPNRGZ | N11: elc_won_MYS_001 | O11: S01aH01 | P11: 0.11007058 | Q11: IMPNRGZ | S11: elc_wof_MYS_001 | T11: S01aH01 | U11: 0.13323642 | V11: IMPNRGZ | X11: 0.12146119 | Y11: 0.047967249 | Z11: S01aH01 | AA11: elc_roadtransport | AC11: elc_buildings | AD11: S01aH01 | AE11: 0.087407209 | AG11: ELC | AH11: S01aH01 | AI11: 0.21018272
C12: S02 | E12: H02 | G12: a | I12: elc_spv_MYS_001 | J12: S01aH02 | K12: 0.059375881 | L12: IMPNRGZ | N12: elc_won_MYS_001 | O12: S01aH02 | P12: 0.024357346 | Q12: IMPNRGZ | S12: elc_wof_MYS_001 | T12: S01aH02 | U12: 0.038795362 | V12: IMPNRGZ | X12: 0.034703196 | Y12: 0.051141553 | Z12: S01aH02 | AA12: elc_roadtransport | AC12: elc_buildings | AD12: S01aH02 | AE12: 0.032869916 | AG12: ELC | AH12: S01aH02 | AI12: 0.16673179
C13: S03 | E13: H03 | G13: a | I13: elc_spv_MYS_001 | J13: S01aH03 | K13: 0.37825169 | L13: IMPNRGZ | N13: elc_won_MYS_001 | O13: S01aH03 | P13: 0.27330436 | Q13: IMPNRGZ | S13: elc_wof_MYS_001 | T13: S01aH03 | U13: 0.27749195 | V13: IMPNRGZ | X13: 0.26027397 | Y13: 0.31732955 | Z13: S01aH03 | AA13: elc_roadtransport | AC13: elc_buildings | AD13: S01aH03 | AE13: 0.32371612 | AG13: ELC | AH13: S01aH03 | AI13: 0.19900707
C14: S04 | I14: elc_spv_MYS_001 | J14: S02aH01 | K14: 0.0035484569 | L14: IMPNRGZ | N14: elc_won_MYS_001 | O14: S02aH01 | P14: 0.015064882 | Q14: IMPNRGZ | S14: elc_wof_MYS_001 | T14: S02aH01 | U14: 0.014762329 | V14: IMPNRGZ | X14: 0.033561644 | Y14: 0.013254108 | Z14: S02aH01 | AA14: elc_roadtransport | AC14: elc_buildings | AD14: S02aH01 | AE14: 0.028517764 | AG14: ELC | AH14: S02aH01 | AI14: 0.17572768
I15: elc_spv_MYS_001 | J15: S02aH02 | K15: 0.015700094 | L15: IMPNRGZ | N15: elc_won_MYS_001 | O15: S02aH02 | P15: 0.0030521094 | Q15: IMPNRGZ | S15: elc_wof_MYS_001 | T15: S02aH02 | U15: 0.0039560928 | V15: IMPNRGZ | X15: 0.0095890411 | Y15: 0.014131218 | Z15: S02aH02 | AA15: elc_roadtransport | AC15: elc_buildings | AD15: S02aH02 | AE15: 0.010088851 | AG15: ELC | AH15: S02aH02 | AI15: 0.14656506
I16: elc_spv_MYS_001 | J16: S02aH03 | K16: 0.097981595 | L16: IMPNRGZ | N16: elc_won_MYS_001 | O16: S02aH03 | P16: 0.041977395 | Q16: IMPNRGZ | S16: elc_wof_MYS_001 | T16: S02aH03 | U16: 0.027999284 | V16: IMPNRGZ | X16: 0.071917808 | Y16: 0.087683166 | Z16: S02aH03 | AA16: elc_roadtransport | AC16: elc_buildings | AD16: S02aH03 | AE16: 0.10477952 | AG16: ELC | AH16: S02aH03 | AI16: 0.13496299
I17: elc_spv_MYS_001 | J17: S03aH01 | K17: 0.0069525799 | L17: IMPNRGZ | N17: elc_won_MYS_001 | O17: S03aH01 | P17: 0.10121408 | Q17: IMPNRGZ | S17: elc_wof_MYS_001 | T17: S03aH01 | U17: 0.063171178 | V17: IMPNRGZ | X17: 0.072716895 | Y17: 0.028717235 | Z17: S03aH01 | AA17: elc_roadtransport | AC17: elc_buildings | AD17: S03aH01 | AE17: 0.045585334 | AG17: ELC | AH17: S03aH01 | AI17: 0.14870507
I18: elc_spv_MYS_001 | J18: S03aH02 | K18: 0.033566219 | L18: IMPNRGZ | N18: elc_won_MYS_001 | O18: S03aH02 | P18: 0.021539302 | Q18: IMPNRGZ | S18: elc_wof_MYS_001 | T18: S03aH02 | U18: 0.018234256 | V18: IMPNRGZ | X18: 0.020776256 | Y18: 0.03061764 | Z18: S03aH02 | AA18: elc_roadtransport | AC18: elc_buildings | AD18: S03aH02 | AE18: 0.018556489 | AG18: ELC | AH18: S03aH02 | AI18: 0.14575489
I19: elc_spv_MYS_001 | J19: S03aH03 | K19: 0.20698902 | L19: IMPNRGZ | N19: elc_won_MYS_001 | O19: S03aH03 | P19: 0.24265475 | Q19: IMPNRGZ | S19: elc_wof_MYS_001 | T19: S03aH03 | U19: 0.1431622 | V19: IMPNRGZ | X19: 0.15582192 | Y19: 0.18998019 | Z19: S03aH03 | AA19: elc_roadtransport | AC19: elc_buildings | AD19: S03aH03 | AE19: 0.17359532 | AG19: ELC | AH19: S03aH03 | AI19: 0.2131869
I20: elc_spv_MYS_001 | J20: S04aH01 | K20: 0.0050769318 | L20: IMPNRGZ | N20: elc_won_MYS_001 | O20: S04aH01 | P20: 0.044948885 | Q20: IMPNRGZ | S20: elc_wof_MYS_001 | T20: S04aH01 | U20: 0.079026292 | V20: IMPNRGZ | X20: 0.063926941 | Y20: 0.025245921 | Z20: S04aH01 | AA20: elc_roadtransport | AC20: elc_buildings | AD20: S04aH01 | AE20: 0.035695569 | AG20: ELC | AH20: S04aH01 | AI20: 0.097103508
I21: elc_spv_MYS_001 | J21: S04aH02 | K21: 0.028183635 | L21: IMPNRGZ | N21: elc_won_MYS_001 | O21: S04aH02 | P21: 0.010999264 | Q21: IMPNRGZ | S21: elc_wof_MYS_001 | T21: S04aH02 | U21: 0.022351173 | V21: IMPNRGZ | X21: 0.01826484 | Y21: 0.026916607 | Z21: S04aH02 | AA21: elc_roadtransport | AC21: elc_buildings | AD21: S04aH02 | AE21: 0.01516302 | AG21: ELC | AH21: S04aH02 | AI21: 0.1129344
I22: elc_spv_MYS_001 | J22: S04aH03 | K22: 0.15798431 | L22: IMPNRGZ | N22: elc_won_MYS_001 | O22: S04aH03 | P22: 0.11081704 | Q22: IMPNRGZ | S22: elc_wof_MYS_001 | T22: S04aH03 | U22: 0.17781346 | V22: IMPNRGZ | X22: 0.1369863 | Y22: 0.16701555 | Z22: S04aH03 | AA22: elc_roadtransport | AC22: elc_buildings | AD22: S04aH03 | AE22: 0.12402489 | AG22: ELC | AH22: S04aH03 | AI22: 0.16181883
I23: elc_spv_MYS_002 | J23: S01aH01 | K23: 0.007047455 | L23: IMPNRGZ | N23: elc_won_MYS_002 | O23: S01aH01 | P23: 0.098260043 | Q23: IMPNRGZ | S23: elc_wof_MYS_002 | T23: S01aH01 | U23: 0.12793864 | V23: IMPNRGZ | AC23: elc_industry | AD23: S01aH01 | AE23: 0.11927246
I24: elc_spv_MYS_002 | J24: S01aH02 | K24: 0.064420252 | L24: IMPNRGZ | N24: elc_won_MYS_002 | O24: S01aH02 | P24: 0.024854052 | Q24: IMPNRGZ | S24: elc_wof_MYS_002 | T24: S01aH02 | U24: 0.039111974 | V24: IMPNRGZ | AC24: elc_industry | AD24: S01aH02 | AE24: 0.034494965
I25: elc_spv_MYS_002 | J25: S01aH03 | K25: 0.37793866 | L25: IMPNRGZ | N25: elc_won_MYS_002 | O25: S01aH03 | P25: 0.28658795 | Q25: IMPNRGZ | S25: elc_wof_MYS_002 | T25: S01aH03 | U25: 0.29209569 | V25: IMPNRGZ | AC25: elc_industry | AD25: S01aH03 | AE25: 0.26278982
I26: elc_spv_MYS_002 | J26: S02aH01 | K26: 0.0032335946 | L26: IMPNRGZ | N26: elc_won_MYS_002 | O26: S02aH01 | P26: 0.017182978 | Q26: IMPNRGZ | S26: elc_wof_MYS_002 | T26: S02aH01 | U26: 0.0076548177 | V26: IMPNRGZ | AC26: elc_industry | AD26: S02aH01 | AE26: 0.032905701
I27: elc_spv_MYS_002 | J27: S02aH02 | K27: 0.014021375 | L27: IMPNRGZ | N27: elc_won_MYS_002 | O27: S02aH02 | P27: 0.0057715859 | Q27: IMPNRGZ | S27: elc_wof_MYS_002 | T27: S02aH02 | U27: 0.0023379913 | V27: IMPNRGZ | AC27: elc_industry | AD27: S02aH02 | AE27: 0.0095041559
I28: elc_spv_MYS_002 | J28: S02aH03 | K28: 0.091501711 | L28: IMPNRGZ | N28: elc_won_MYS_002 | O28: S02aH03 | P28: 0.044649266 | Q28: IMPNRGZ | S28: elc_wof_MYS_002 | T28: S02aH03 | U28: 0.015145492 | V28: IMPNRGZ | AC28: elc_industry | AD28: S02aH03 | AE28: 0.072819041
I29: elc_spv_MYS_002 | J29: S03aH01 | K29: 0.0070091864 | L29: IMPNRGZ | N29: elc_won_MYS_002 | O29: S03aH01 | P29: 0.10130962 | Q29: IMPNRGZ | S29: elc_wof_MYS_002 | T29: S03aH01 | U29: 0.05012262 | V29: IMPNRGZ | AC29: elc_industry | AD29: S03aH01 | AE29: 0.071448323
I30: elc_spv_MYS_002 | J30: S03aH02 | K30: 0.034002242 | L30: IMPNRGZ | N30: elc_won_MYS_002 | O30: S03aH02 | P30: 0.030959452 | Q30: IMPNRGZ | S30: elc_wof_MYS_002 | T30: S03aH02 | U30: 0.017181191 | V30: IMPNRGZ | AC30: elc_industry | AD30: S03aH02 | AE30: 0.020706035
I31: elc_spv_MYS_002 | J31: S03aH03 | K31: 0.20855885 | L31: IMPNRGZ | N31: elc_won_MYS_002 | O31: S03aH03 | P31: 0.22762129 | Q31: IMPNRGZ | S31: elc_wof_MYS_002 | T31: S03aH03 | U31: 0.10841247 | V31: IMPNRGZ | AC31: elc_industry | AD31: S03aH03 | AE31: 0.15711355
I32: elc_spv_MYS_002 | J32: S04aH01 | K32: 0.0042678985 | L32: IMPNRGZ | N32: elc_won_MYS_002 | O32: S04aH01 | P32: 0.043629815 | Q32: IMPNRGZ | S32: elc_wof_MYS_002 | T32: S04aH01 | U32: 0.095020052 | V32: IMPNRGZ | AC32: elc_industry | AD32: S04aH01 | AE32: 0.063050391
I33: elc_spv_MYS_002 | J33: S04aH02 | K33: 0.028973332 | L33: IMPNRGZ | N33: elc_won_MYS_002 | O33: S04aH02 | P33: 0.010727788 | Q33: IMPNRGZ | S33: elc_wof_MYS_002 | T33: S04aH02 | U33: 0.027677483 | V33: IMPNRGZ | AC33: elc_industry | AD33: S04aH02 | AE33: 0.018276631
I34: elc_spv_MYS_002 | J34: S04aH03 | K34: 0.15902544 | L34: IMPNRGZ | N34: elc_won_MYS_002 | O34: S04aH03 | P34: 0.10844616 | Q34: IMPNRGZ | S34: elc_wof_MYS_002 | T34: S04aH03 | U34: 0.21730157 | V34: IMPNRGZ | AC34: elc_industry | AD34: S04aH03 | AE34: 0.13761894
I35: elc_spv_MYS_003 | J35: S01aH01 | K35: 0.0071436917 | L35: IMPNRGZ | N35: elc_won_MYS_003 | O35: S01aH01 | P35: 0.087573766 | Q35: IMPNRGZ | S35: elc_wof_MYS_003 | T35: S01aH01 | U35: 0.12190068 | V35: IMPNRGZ
I36: elc_spv_MYS_003 | J36: S01aH02 | K36: 0.06457837 | L36: IMPNRGZ | N36: elc_won_MYS_003 | O36: S01aH02 | P36: 0.020044744 | Q36: IMPNRGZ | S36: elc_wof_MYS_003 | T36: S01aH02 | U36: 0.039033577 | V36: IMPNRGZ
I37: elc_spv_MYS_003 | J37: S01aH03 | K37: 0.36776587 | L37: IMPNRGZ | N37: elc_won_MYS_003 | O37: S01aH03 | P37: 0.24291873 | Q37: IMPNRGZ | S37: elc_wof_MYS_003 | T37: S01aH03 | U37: 0.28717807 | V37: IMPNRGZ
I38: elc_spv_MYS_003 | J38: S02aH01 | K38: 0.0034305476 | L38: IMPNRGZ | N38: elc_won_MYS_003 | O38: S02aH01 | P38: 0.015766308 | Q38: IMPNRGZ | S38: elc_wof_MYS_003 | T38: S02aH01 | U38: 0.011992045 | V38: IMPNRGZ
I39: elc_spv_MYS_003 | J39: S02aH02 | K39: 0.015545923 | L39: IMPNRGZ | N39: elc_won_MYS_003 | O39: S02aH02 | P39: 0.0045785105 | Q39: IMPNRGZ | S39: elc_wof_MYS_003 | T39: S02aH02 | U39: 0.0033536524 | V39: IMPNRGZ
I40: elc_spv_MYS_003 | J40: S02aH03 | K40: 0.095290278 | L40: IMPNRGZ | N40: elc_won_MYS_003 | O40: S02aH03 | P40: 0.05086284 | Q40: IMPNRGZ | S40: elc_wof_MYS_003 | T40: S02aH03 | U40: 0.02286934 | V40: IMPNRGZ
I41: elc_spv_MYS_003 | J41: S03aH01 | K41: 0.0080691462 | L41: IMPNRGZ | N41: elc_won_MYS_003 | O41: S03aH01 | P41: 0.11215147 | Q41: IMPNRGZ | S41: elc_wof_MYS_003 | T41: S03aH01 | U41: 0.054670433 | V41: IMPNRGZ
I42: elc_spv_MYS_003 | J42: S03aH02 | K42: 0.036407196 | L42: IMPNRGZ | N42: elc_won_MYS_003 | O42: S03aH02 | P42: 0.030540962 | Q42: IMPNRGZ | S42: elc_wof_MYS_003 | T42: S03aH02 | U42: 0.017110875 | V42: IMPNRGZ
I43: elc_spv_MYS_003 | J43: S03aH03 | K43: 0.20878156 | L43: IMPNRGZ | N43: elc_won_MYS_003 | O43: S03aH03 | P43: 0.27259715 | Q43: IMPNRGZ | S43: elc_wof_MYS_003 | T43: S03aH03 | U43: 0.1076084 | V43: IMPNRGZ
I44: elc_spv_MYS_003 | J44: S04aH01 | K44: 0.0055734324 | L44: IMPNRGZ | N44: elc_won_MYS_003 | O44: S04aH01 | P44: 0.045052594 | Q44: IMPNRGZ | S44: elc_wof_MYS_003 | T44: S04aH01 | U44: 0.092475692 | V44: IMPNRGZ
I45: elc_spv_MYS_003 | J45: S04aH02 | K45: 0.031061799 | L45: IMPNRGZ | N45: elc_won_MYS_003 | O45: S04aH02 | P45: 0.011057784 | Q45: IMPNRGZ | S45: elc_wof_MYS_003 | T45: S04aH02 | U45: 0.027124838 | V45: IMPNRGZ
I46: elc_spv_MYS_003 | J46: S04aH03 | K46: 0.15635219 | L46: IMPNRGZ | N46: elc_won_MYS_003 | O46: S04aH03 | P46: 0.10685513 | Q46: IMPNRGZ | S46: elc_wof_MYS_003 | T46: S04aH03 | U46: 0.2146824 | V46: IMPNRGZ
... I130: elc_spv_MYS_010 | J130: S04aH03 | K130: 0.1868431 | L130: IMPNRGZ | N130: elc_won_MYS_010 | O130: S04aH03 | P130: 0.21877503 | Q130: IMPNRGZ | S130: elc_wof_MYS_010 | T130: S04aH03 | U130: 0.12392085 | V130: IMPNRGZ
I131: elc_spv_MYS_011 | J131: S01aH01 | K131: 0.0039083554 | L131: IMPNRGZ
...

Sheet ts_024
C9: =IF(A11="x","DeActivated","~TimeSlices") -> DeActivated | I9: =IF(A11="x","DeActivated","~TFM_DINS-AT") -> DeActivated | N9: =IF(A11="x","DeActivated","~TFM_DINS-AT") -> DeActivated | S9: =IF(A11="x","DeActivated","~TFM_DINS-AT") -> DeActivated | X9: =IF(A11="x","DeActivated","~TFM_DINS-AT") -> DeActivated | AC9: =IF(A11="x","DeActivated","~TFM_DINS-AT") -> DeActivated | AG9: =IF(A11="x","DeActivated","~TFM_DINS-AT") -> DeActivated | AK9: =IF(A11="x","DeActivated","~TFM_INS-AT") -> DeActivated
A10: ts_024 | C10: season | D10: weekly | E10: daynite | F10: wparent | G10: dparent | I10: commodity | J10: timeslice | K10: com_fr | L10: process | N10: commodity | O10: timeslice | P10: com_fr | Q10: process | S10: commodity | T10: timeslice | U10: com_fr | V10: process | X10: g_yrfr | Y10: com_fr | Z10: timeslice | AA10: commodity | AC10: commodity | AD10: timeslice | AE10: com_fr | AG10: commodity | AH10: timeslice | AI10: com_pkflx | AK10: Year | AL10: timeslice | AM10: ncap_afs | AN10: pset_ci
A11: =IFERROR(IF(Veda!D5=A10,"ok","x"),"") -> x | C11: S01 | D11: a | E11: H01 | F11: S01,S02,S03,S04 | G11: a | I11: elc_spv_MYS_001 | J11: S01aH01 | K11: 0.0063895928 | L11: IMPNRGZ | N11: elc_won_MYS_001 | O11: S01aH01 | P11: 0.11007058 | Q11: IMPNRGZ | S11: elc_wof_MYS_001 | T11: S01aH01 | U11: 0.13323642 | V11: IMPNRGZ | X11: 0.12146119 | Y11: 0.047967249 | Z11: S01aH01 | AA11: elc_roadtransport | AC11: elc_buildings | AD11: S01aH01 | AE11: 0.087407209 | AG11: ELC | AH11: S01aH01 | AI11: 0.21018272
C12: S02 | E12: H02 | G12: a | I12: elc_spv_MYS_001 | J12: S01aH02 | K12: 0.059375881 | L12: IMPNRGZ | N12: elc_won_MYS_001 | O12: S01aH02 | P12: 0.024357346 | Q12: IMPNRGZ | S12: elc_wof_MYS_001 | T12: S01aH02 | U12: 0.038795362 | V12: IMPNRGZ | X12: 0.034703196 | Y12: 0.051141553 | Z12: S01aH02 | AA12: elc_roadtransport | AC12: elc_buildings | AD12: S01aH02 | AE12: 0.032869916 | AG12: ELC | AH12: S01aH02 | AI12: 0.16673179
C13: S03 | E13: H03 | G13: a | I13: elc_spv_MYS_001 | J13: S01aH03 | K13: 0.045174628 | L13: IMPNRGZ | N13: elc_won_MYS_001 | O13: S01aH03 | P13: 0.013781327 | Q13: IMPNRGZ | S13: elc_wof_MYS_001 | T13: S01aH03 | U13: 0.019805003 | V13: IMPNRGZ | X13: 0.017351598 | Y13: 0.021968194 | Z13: S01aH03 | AA13: elc_roadtransport | AC13: elc_buildings | AD13: S01aH03 | AE13: 0.019011407 | AG13: ELC | AH13: S01aH03 | AI13: 0.11508777
C14: S04 | E14: H04 | G14: a | I14: elc_spv_MYS_001 | J14: S01aH04 | K14: 0.21085166 | L14: IMPNRGZ | N14: elc_won_MYS_001 | O14: S01aH04 | P14: 0.065844083 | Q14: IMPNRGZ | S14: elc_wof_MYS_001 | T14: S01aH04 | U14: 0.074167189 | V14: IMPNRGZ | X14: 0.069406393 | Y14: 0.087066604 | Z14: S01aH04 | AA14: elc_roadtransport | AC14: elc_buildings | AD14: S01aH04 | AE14: 0.087274611 | AG14: ELC | AH14: S01aH04 | AI14: 0.18741225
E15: H05 | G15: a | I15: elc_spv_MYS_001 | J15: S01aH05 | K15: 0.1222254 | L15: IMPNRGZ | N15: elc_won_MYS_001 | O15: S01aH05 | P15: 0.082180457 | Q15: IMPNRGZ | S15: elc_wof_MYS_001 | T15: S01aH05 | U15: 0.066706571 | V15: IMPNRGZ | X15: 0.069406393 | Y15: 0.11659266 | Z15: S01aH05 | AA15: elc_roadtransport | AC15: elc_buildings | AD15: S01aH05 | AE15: 0.089371754 | AG15: ELC | AH15: S01aH05 | AI15: 0.17483247
E16: H06 | G16: a | I16: elc_spv_MYS_001 | J16: S01aH06 | K16: 0 | L16: IMPNRGZ | N16: elc_won_MYS_001 | O16: S01aH06 | P16: 0.1114985 | Q16: IMPNRGZ | S16: elc_wof_MYS_001 | T16: S01aH06 | U16: 0.11681318 | V16: IMPNRGZ | X16: 0.10410959 | Y16: 0.091702094 | Z16: S01aH06 | AA16: elc_roadtransport | AC16: elc_buildings | AD16: S01aH06 | AE16: 0.12805835 | AG16: ELC | AH16: S01aH06 | AI16: 0.17346137
I17: elc_spv_MYS_001 | J17: S02aH01 | K17: 0.0035484569 | L17: IMPNRGZ | N17: elc_won_MYS_001 | O17: S02aH01 | P17: 0.015064882 | Q17: IMPNRGZ | S17: elc_wof_MYS_001 | T17: S02aH01 | U17: 0.014762329 | V17: IMPNRGZ | X17: 0.033561644 | Y17: 0.013254108 | Z17: S02aH01 | AA17: elc_roadtransport | AC17: elc_buildings | AD17: S02aH01 | AE17: 0.028517764 | AG17: ELC | AH17: S02aH01 | AI17: 0.17572768
I18: elc_spv_MYS_001 | J18: S02aH02 | K18: 0.015700094 | L18: IMPNRGZ | N18: elc_won_MYS_001 | O18: S02aH02 | P18: 0.0030521094 | Q18: IMPNRGZ | S18: elc_wof_MYS_001 | T18: S02aH02 | U18: 0.0039560928 | V18: IMPNRGZ | X18: 0.0095890411 | Y18: 0.014131218 | Z18: S02aH02 | AA18: elc_roadtransport | AC18: elc_buildings | AD18: S02aH02 | AE18: 0.010088851 | AG18: ELC | AH18: S02aH02 | AI18: 0.14656506
I19: elc_spv_MYS_001 | J19: S02aH03 | K19: 0.011421992 | L19: IMPNRGZ | N19: elc_won_MYS_001 | O19: S02aH03 | P19: 0.0014419981 | Q19: IMPNRGZ | S19: elc_wof_MYS_001 | T19: S02aH03 | U19: 0.0019055582 | V19: IMPNRGZ | X19: 0.0047945205 | Y19: 0.0060701589 | Z19: S02aH03 | AA19: elc_roadtransport | AC19: elc_buildings | AD19: S02aH03 | AE19: 0.0060943128 | AG19: ELC | AH19: S02aH03 | AI19: 0.080144397
I20: elc_spv_MYS_001 | J20: S02aH04 | K20: 0.056843261 | L20: IMPNRGZ | N20: elc_won_MYS_001 | O20: S02aH04 | P20: 0.0058214158 | Q20: IMPNRGZ | S20: elc_wof_MYS_001 | T20: S02aH04 | U20: 0.0082521605 | V20: IMPNRGZ | X20: 0.019178082 | Y20: 0.024057877 | Z20: S02aH04 | AA20: elc_roadtransport | AC20: elc_buildings | AD20: S02aH04 | AE20: 0.028429528 | AG20: ELC | AH20: S02aH04 | AI20: 0.1170154
I21: elc_spv_MYS_001 | J21: S02aH05 | K21: 0.029716341 | L21: IMPNRGZ | N21: elc_won_MYS_001 | O21: S02aH05 | P21: 0.013623621 | Q21: IMPNRGZ | S21: elc_wof_MYS_001 | T21: S02aH05 | U21: 0.00834321 | V21: IMPNRGZ | X21: 0.019178082 | Y21: 0.032216394 | Z21: S02aH05 | AA21: elc_roadtransport | AC21: elc_buildings | AD21: S02aH05 | AE21: 0.029359684 | AG21: ELC | AH21: S02aH05 | AI21: 0.10017446
I22: elc_spv_MYS_001 | J22: S02aH06 | K22: 0 | L22: IMPNRGZ | N22: elc_won_MYS_001 | O22: S02aH06 | P22: 0.02109036 | Q22: IMPNRGZ | S22: elc_wof_MYS_001 | T22: S02aH06 | U22: 0.0094983555 | V22: IMPNRGZ | X22: 0.028767123 | Y22: 0.025338737 | Z22: S02aH06 | AA22: elc_roadtransport | AC22: elc_buildings | AD22: S02aH06 | AE22: 0.040895992 | AG22: ELC | AH22: S02aH06 | AI22: 0.12286431
I23: elc_spv_MYS_001 | J23: S03aH01 | K23: 0.0069525799 | L23: IMPNRGZ | N23: elc_won_MYS_001 | O23: S03aH01 | P23: 0.10121408 | Q23: IMPNRGZ | S23: elc_wof_MYS_001 | T23: S03aH01 | U23: 0.063171178 | V23: IMPNRGZ | X23: 0.072716895 | Y23: 0.028717235 | Z23: S03aH01 | AA23: elc_roadtransport | AC23: elc_buildings | AD23: S03aH01 | AE23: 0.045585334 | AG23: ELC | AH23: S03aH01 | AI23: 0.14870507
I24: elc_spv_MYS_001 | J24: S03aH02 | K24: 0.033566219 | L24: IMPNRGZ | N24: elc_won_MYS_001 | O24: S03aH02 | P24: 0.021539302 | Q24: IMPNRGZ | S24: elc_wof_MYS_001 | T24: S03aH02 | U24: 0.018234256 | V24: IMPNRGZ | X24: 0.020776256 | Y24: 0.03061764 | Z24: S03aH02 | AA24: elc_roadtransport | AC24: elc_buildings | AD24: S03aH02 | AE24: 0.018556489 | AG24: ELC | AH24: S03aH02 | AI24: 0.14575489
I25: elc_spv_MYS_001 | J25: S03aH03 | K25: 0.02476856 | L25: IMPNRGZ | N25: elc_won_MYS_001 | O25: S03aH03 | P25: 0.010019747 | Q25: IMPNRGZ | S25: elc_wof_MYS_001 | T25: S03aH03 | U25: 0.0090518446 | V25: IMPNRGZ | X25: 0.010388128 | Y25: 0.013152011 | Z25: S03aH03 | AA25: elc_roadtransport | AC25: elc_buildings | AD25: S03aH03 | AE25: 0.010408796 | AG25: ELC | AH25: S03aH03 | AI25: 0.15229378
I26: elc_spv_MYS_001 | J26: S03aH04 | K26: 0.11692927 | L26: IMPNRGZ | N26: elc_won_MYS_001 | O26: S03aH04 | P26: 0.048116465 | Q26: IMPNRGZ | S26: elc_wof_MYS_001 | T26: S03aH04 | U26: 0.040829435 | V26: IMPNRGZ | X26: 0.041552511 | Y26: 0.052125401 | Z26: S03aH04 | AA26: elc_roadtransport | AC26: elc_buildings | AD26: S03aH04 | AE26: 0.046016662 | AG26: ELC | AH26: S03aH04 | AI26: 0.19640783
I27: elc_spv_MYS_001 | J27: S03aH05 | K27: 0.065291192 | L27: IMPNRGZ | N27: elc_won_MYS_001 | O27: S03aH05 | P27: 0.07276278 | Q27: IMPNRGZ | S27: elc_wof_MYS_001 | T27: S03aH05 | U27: 0.044466251 | V27: IMPNRGZ | X27: 0.041552511 | Y27: 0.069802186 | Z27: S03aH05 | AA27: elc_roadtransport | AC27: elc_buildings | AD27: S03aH05 | AE27: 0.046972758 | AG27: ELC | AH27: S03aH05 | AI27: 0.20337612
I28: elc_spv_MYS_001 | J28: S03aH06 | K28: 0 | L28: IMPNRGZ | N28: elc_won_MYS_001 | O28: S03aH06 | P28: 0.11175576 | Q28: IMPNRGZ | S28: elc_wof_MYS_001 | T28: S03aH06 | U28: 0.048814673 | V28: IMPNRGZ | X28: 0.062328767 | Y28: 0.054900596 | Z28: S03aH06 | AA28: elc_roadtransport | AC28: elc_buildings | AD28: S03aH06 | AE28: 0.070197102 | AG28: ELC | AH28: S03aH06 | AI28: 0.18849938
... I34: elc_spv_MYS_001 | J34: S04aH06 | K34: 0 | L34: IMPNRGZ | N34: elc_won_MYS_001 | O34: S04aH06 | P34: 0.045428406 | Q34: IMPNRGZ | S34: elc_wof_MYS_001 | T34: S04aH06 | U34: 0.074611424 | V34: IMPNRGZ | X34: 0.054794521 | Y34: 0.04826426 | Z34: S04aH06 | AA34: elc_roadtransport | AC34: elc_buildings | AD34: S04aH06 | AE34: 0.051174968 | AG34: ELC | AH34: S04aH06 | AI34: 0.14374606
I35: elc_spv_MYS_002 | J35: S01aH01 | K35: 0.007047455 | L35: IMPNRGZ | N35: elc_won_MYS_002 | O35: S01aH01 | P35: 0.098260043 | Q35: IMPNRGZ | S35: elc_wof_MYS_002 | T35: S01aH01 | U35: 0.12793864 | V35: IMPNRGZ | AC35: elc_industry | AD35: S01aH01 | AE35: 0.11927246
I36: elc_spv_MYS_002 | J36: S01aH02 | K36: 0.064420252 | L36: IMPNRGZ | N36: elc_won_MYS_002 | O36: S01aH02 | P36: 0.024854052 | Q36: IMPNRGZ | S36: elc_wof_MYS_002 | T36: S01aH02 | U36: 0.039111974 | V36: IMPNRGZ | AC36: elc_industry | AD36: S01aH02 | AE36: 0.034494965
I37: elc_spv_MYS_002 | J37: S01aH03 | K37: 0.047160148 | L37: IMPNRGZ | N37: elc_won_MYS_002 | O37: S01aH03 | P37: 0.012986298 | Q37: IMPNRGZ | S37: elc_wof_MYS_002 | T37: S01aH03 | U37: 0.020283269 | V37: IMPNRGZ | AC37: elc_industry | AD37: S01aH03 | AE37: 0.017383581
I38: elc_spv_MYS_002 | J38: S01aH04 | K38: 0.2086963 | L38: IMPNRGZ | N38: elc_won_MYS_002 | O38: S01aH04 | P38: 0.062259816 | Q38: IMPNRGZ | S38: elc_wof_MYS_002 | T38: S01aH04 | U38: 0.080266242 | V38: IMPNRGZ | AC38: elc_industry | AD38: S01aH04 | AE38: 0.070127484
I39: elc_spv_MYS_002 | J39: S01aH05 | K39: 0.12208221 | L39: IMPNRGZ | N39: elc_won_MYS_002 | O39: S01aH05 | P39: 0.082719771 | Q39: IMPNRGZ | S39: elc_wof_MYS_002 | T39: S01aH05 | U39: 0.074538465 | V39: IMPNRGZ | AC39: elc_industry | AD39: S01aH05 | AE39: 0.070238263
I40: elc_spv_MYS_002 | J40: S01aH06 | K40: 0 | L40: IMPNRGZ | N40: elc_won_MYS_002 | O40: S01aH06 | P40: 0.12862207 | Q40: IMPNRGZ | S40: elc_wof_MYS_002 | T40: S01aH06 | U40: 0.11700772 | V40: IMPNRGZ | AC40: elc_industry | AD40: S01aH06 | AE40: 0.10504049
I41: elc_spv_MYS_002 | J41: S02aH01 | K41: 0.0032335946 | L41: IMPNRGZ | N41: elc_won_MYS_002 | O41: S02aH01 | P41: 0.017182978 | Q41: IMPNRGZ | S41: elc_wof_MYS_002 | T41: S02aH01 | U41: 0.0076548177 | V41: IMPNRGZ | AC41: elc_industry | AD41: S02aH01 | AE41: 0.032905701
I42: elc_spv_MYS_002 | J42: S02aH02 | K42: 0.014021375 | L42: IMPNRGZ | N42: elc_won_MYS_002 | O42: S02aH02 | P42: 0.0057715859 | Q42: IMPNRGZ | S42: elc_wof_MYS_002 | T42: S02aH02 | U42: 0.0023379913 | V42: IMPNRGZ | AC42: elc_industry | AD42: S02aH02 | AE42: 0.0095041559
I43: elc_spv_MYS_002 | J43: S02aH03 | K43: 0.010560515 | L43: IMPNRGZ | N43: elc_won_MYS_002 | O43: S02aH03 | P43: 0.0029657551 | Q43: IMPNRGZ | S43: elc_wof_MYS_002 | T43: S02aH03 | U43: 0.0013134634 | V43: IMPNRGZ | AC43: elc_industry | AD43: S02aH03 | AE43: 0.0048075372
I44: elc_spv_MYS_002 | J44: S02aH04 | K44: 0.052056609 | L44: IMPNRGZ | N44: elc_won_MYS_002 | O44: S02aH04 | P44: 0.014885478 | Q44: IMPNRGZ | S44: elc_wof_MYS_002 | T44: S02aH04 | U44: 0.0053294518 | V44: IMPNRGZ | AC44: elc_industry | AD44: S02aH04 | AE44: 0.019444206
I45: elc_spv_MYS_002 | J45: S02aH05 | K45: 0.028668498 | L45: IMPNRGZ | N45: elc_won_MYS_002 | O45: S02aH05 | P45: 0.012923317 | Q45: IMPNRGZ | S45: elc_wof_MYS_002 | T45: S02aH05 | U45: 0.0043281442 | V45: IMPNRGZ | AC45: elc_industry | AD45: S02aH05 | AE45: 0.019493341
I46: elc_spv_MYS_002 | J46: S02aH06 | K46: 0.0002160893 | L46: IMPNRGZ | N46: elc_won_MYS_002 | O46: S02aH06 | P46: 0.013874715 | Q46: IMPNRGZ | S46: elc_wof_MYS_002 | T46: S02aH06 | U46: 0.0041744326 | V46: IMPNRGZ | AC46: elc_industry | AD46: S02aH06 | AE46: 0.029073957
... I58: elc_spv_MYS_002 | J58: S04aH06 | K58: 0 | L58: IMPNRGZ | N58: elc_won_MYS_002 | O58: S04aH06 | P58: 0.048952493 | Q58: IMPNRGZ | S58: elc_wof_MYS_002 | T58: S04aH06 | U58: 0.094878598 | V58: IMPNRGZ | AC58: elc_industry | AD58: S04aH06 | AE58: 0.055130245
I59: elc_spv_MYS_003 | J59: S01aH01 | K59: 0.0071436917 | L59: IMPNRGZ | N59: elc_won_MYS_003 | O59: S01aH01 | P59: 0.087573766 | Q59: IMPNRGZ | S59: elc_wof_MYS_003 | T59: S01aH01 | U59: 0.12190068 | V59: IMPNRGZ
I60: elc_spv_MYS_003 | J60: S01aH02 | K60: 0.06457837 | L60: IMPNRGZ | N60: elc_won_MYS_003 | O60: S01aH02 | P60: 0.020044744 | Q60: IMPNRGZ | S60: elc_wof_MYS_003 | T60: S01aH02 | U60: 0.039033577 | V60: IMPNRGZ
I61: elc_spv_MYS_003 | J61: S01aH03 | K61: 0.048133608 | L61: IMPNRGZ | N61: elc_won_MYS_003 | O61: S01aH03 | P61: 0.01093128 | Q61: IMPNRGZ | S61: elc_wof_MYS_003 | T61: S01aH03 | U61: 0.020681978 | V61: IMPNRGZ
I62: elc_spv_MYS_003 | J62: S01aH04 | K62: 0.2104196 | L62: IMPNRGZ | N62: elc_won_MYS_003 | O62: S01aH04 | P62: 0.056749784 | Q62: IMPNRGZ | S62: elc_wof_MYS_003 | T62: S01aH04 | U62: 0.0817025 | V62: IMPNRGZ
I63: elc_spv_MYS_003 | J63: S01aH05 | K63: 0.10921266 | L63: IMPNRGZ | N63: elc_won_MYS_003 | O63: S01aH05 | P63: 0.074862129 | Q63: IMPNRGZ | S63: elc_wof_MYS_003 | T63: S01aH05 | U63: 0.074618246 | V63: IMPNRGZ
I64: elc_spv_MYS_003 | J64: S01aH06 | K64: 0 | L64: IMPNRGZ | N64: elc_won_MYS_003 | O64: S01aH06 | P64: 0.10037554 | Q64: IMPNRGZ | S64: elc_wof_MYS_003 | T64: S01aH06 | U64: 0.11017535 | V64: IMPNRGZ
...

Sheet ts_036
C9: =IF(A11="x","DeActivated","~TimeSlices") -> DeActivated | I9: =IF(A11="x","DeActivated","~TFM_DINS-AT") -> DeActivated | N9: =IF(A11="x","DeActivated","~TFM_DINS-AT") -> DeActivated | S9: =IF(A11="x","DeActivated","~TFM_DINS-AT") -> DeActivated | X9: =IF(A11="x","DeActivated","~TFM_DINS-AT") -> DeActivated | AC9: =IF(A11="x","DeActivated","~TFM_DINS-AT") -> DeActivated | AG9: =IF(A11="x","DeActivated","~TFM_DINS-AT") -> DeActivated | AK9: =IF(A11="x","DeActivated","~TFM_INS-AT") -> DeActivated
A10: ts_036 | C10: season | D10: weekly | E10: daynite | F10: wparent | G10: dparent | I10: commodity | J10: timeslice | K10: com_fr | L10: process | N10: commodity | O10: timeslice | P10: com_fr | Q10: process | S10: commodity | T10: timeslice | U10: com_fr | V10: process | X10: g_yrfr | Y10: com_fr | Z10: timeslice | AA10: commodity | AC10: commodity | AD10: timeslice | AE10: com_fr | AG10: commodity | AH10: timeslice | AI10: com_pkflx | AK10: Year | AL10: timeslice | AM10: ncap_afs | AN10: pset_ci
A11: =IFERROR(IF(Veda!D5=A10,"ok","x"),"") -> x | C11: S01 | D11: a | E11: H01 | F11: S01,S02,S03,S04,S05,S06 | G11: a | I11: elc_spv_MYS_001 | J11: S01aH01 | K11: 1.3380513e-06 | L11: IMPNRGZ | N11: elc_won_MYS_001 | O11: S01aH01 | P11: 0.027953093 | Q11: IMPNRGZ | S11: elc_wof_MYS_001 | T11: S01aH01 | U11: 0.048797819 | V11: IMPNRGZ | X11: 0.018378995 | Y11: 0.0072582022 | Z11: S01aH01 | AA11: elc_roadtransport | AC11: elc_buildings | AD11: S01aH01 | AE11: 0.011456211 | AG11: ELC | AH11: S01aH01 | AI11: 0.072000356
C12: S02 | E12: H02 | G12: a | I12: elc_spv_MYS_001 | J12: S01aH02 | K12: 0.0090541613 | L12: IMPNRGZ | N12: elc_won_MYS_001 | O12: S01aH02 | P12: 0.005347523 | Q12: IMPNRGZ | S12: elc_wof_MYS_001 | T12: S01aH02 | U12: 0.013964361 | V12: IMPNRGZ | X12: 0.0052511416 | Y12: 0.0077385244 | Z12: S01aH02 | AA12: elc_roadtransport | AC12: elc_buildings | AD12: S01aH02 | AE12: 0.00466301 | AG12: ELC | AH12: S01aH02 | AI12: 0.10608061
C13: S03 | E13: H03 | G13: a | I13: elc_spv_MYS_001 | J13: S01aH03 | K13: 0.0068108365 | L13: IMPNRGZ | N13: elc_won_MYS_001 | O13: S01aH03 | P13: 0.0029335242 | Q13: IMPNRGZ | S13: elc_wof_MYS_001 | T13: S01aH03 | U13: 0.0073017095 | V13: IMPNRGZ | X13: 0.0026255708 | Y13: 0.0033241346 | Z13: S01aH03 | AA13: elc_roadtransport | AC13: elc_buildings | AD13: S01aH03 | AE13: 0.0025343908 | AG13: ELC | AH13: S01aH03 | AI13: 0.069244113
C14: S04 | E14: H04 | G14: a | I14: elc_spv_MYS_001 | J14: S01aH04 | K14: 0.030214741 | L14: IMPNRGZ | N14: elc_won_MYS_001 | O14: S01aH04 | P14: 0.014717982 | Q14: IMPNRGZ | S14: elc_wof_MYS_001 | T14: S01aH04 | U14: 0.027550919 | V14: IMPNRGZ | X14: 0.010502283 | Y14: 0.013174552 | Z14: S01aH04 | AA14: elc_roadtransport | AC14: elc_buildings | AD14: S01aH04 | AE14: 0.010985054 | AG14: ELC | AH14: S01aH04 | AI14: 0.05182352
