Workbook

Sheet Veda
G1: 1-8
D2: ="~Inputcell: "&_xlfn.TEXTJOIN(",",TRUE,G1:EE1) -> ~Inputcell: 1-8 | K2: CO2 price | N2: demand
D3: 1 | K3: 300 | L3: C2 | N3: base | O3: C4
K4: 200 | L4: C3 | N4: high | O4: C1
D5: =VLOOKUP(D3,$C$9:$E$999,2,FALSE) -> base | E5: =VLOOKUP(D3,$C$9:$E$999,3,FALSE) -> 0 | K5: 100 | L5: C4
K6: 0 | L6: C7
B7: ~Scenmap
A8: priority | B8: scen | C8: case_no | D8: demand | E8: co2price | AM8: bio price multiplier
A9: 5 | B9: =_xlfn.TEXTJOIN(CHAR(183),TRUE,D9,TEXT(E9,"$000")) -> base·$000 | C9: 1 | D9: base | E9: 0 | S9: IEA | AG9: 1 | AH9: ts_annual | AI9: xAnn | AJ9: 1 | AK9: C1 | AL9: e 1.5 deg no OS | AM9: 5
A10: 5 | B10: =_xlfn.TEXTJOIN(CHAR(183),TRUE,D10,TEXT(E10,"$000")) -> base·$100 | C10: =C9+1 -> 2 | D10: base | E10: 100 | S10: 2022 | AG10: 2 | AH10: ts_12t | AI10: x12 | AJ10: 1 | AK10: C2 | AL10: d 1.5 deg OS | AM10: 4
A11: 5 | B11: =_xlfn.TEXTJOIN(CHAR(183),TRUE,D11,TEXT(E11,"$000")) -> base·$200 | C11: =C10+1 -> 3 | D11: base | E11: 200 | S11: =SUMIFS(iea_data!I3:I9999,iea_data!$B$3:$B$9999,Veda!$S$10)+T28-T29 -> 177.03 | T11: base-year generation (TWh) | AG11: 3 | AH11: ts_012 | AI11: =AH11 -> ts_012 | AJ11: 1 | AK11: C3 | AL11: c 2 deg (67%) | AM11: 3
A12: 5 | B12: =_xlfn.TEXTJOIN(CHAR(183),TRUE,D12,TEXT(E12,"$000")) -> base·$300 | C12: =C11+1 -> 4 | D12: base | E12: 300 | S12: =SUMIFS(iea_data!J3:J9999,iea_data!$B$3:$B$9999,Veda!$S$10) -> 0 | AG12: 4 | AH12: ts_030 | AI12: =AH12 -> ts_030 | AJ12: 1 | AK12: C4 | AL12: b 2 deg (50%) | AM12: 3
A13: 5 | B13: =_xlfn.TEXTJOIN(CHAR(183),TRUE,D13,TEXT(E13,"$000")) -> high·$000 | C13: =C12+1 -> 5 | D13: high | E13: =E9 -> 0 | AG13: 5 | AH13: ts_048 | AI13: =AH13 -> ts_048 | AJ13: 1 | AK13: C7 | AL13: a 3 deg | AM13: 1.5
A14: 5 | B14: =_xlfn.TEXTJOIN(CHAR(183),TRUE,D14,TEXT(E14,"$000")) -> high·$100 | C14: =C13+1 -> 6 | D14: high | E14: =E10 -> 100 | G14: Electricity growth relative to 2020 | H14: =VLOOKUP($D$5,$N$3:$O$5,2,FALSE) -> C4 | I14: =SUMIFS(ar6_r10!$F$2:$F$999,ar6_r10!$A$2:$A$999,Veda!$E$5,ar6_r10!$C$2:$C$999,Veda!I$17,ar6_r10!$M$2:$M$999,Veda!$G14) -> 0 | J14: =SUMIFS(ar6_r10!$F$2:$F$999,ar6_r10!$A$2:$A$999,$H$14,ar6_r10!$C$2:$C$999,Veda!J$17,ar6_r10!$M$2:$M$999,Veda!$G14) -> 1.05 | K14: =SUMIFS(ar6_r10!$F$2:$F$999,ar6_r10!$A$2:$A$999,$H$14,ar6_r10!$C$2:$C$999,Veda!K$17,ar6_r10!$M$2:$M$999,Veda!$G14) -> 1.17 | L14: =SUMIFS(ar6_r10!$F$2:$F$999,ar6_r10!$A$2:$A$999,$H$14,ar6_r10!$C$2:$C$999,Veda!L$17,ar6_r10!$M$2:$M$999,Veda!$G14) -> 1.29 | M14: =SUMIFS(ar6_r10!$F$2:$F$999,ar6_r10!$A$2:$A$999,$H$14,ar6_r10!$C$2:$C$999,Veda!M$17,ar6_r10!$M$2:$M$999,Veda!$G14) -> 1.42 | N14: =SUMIFS(ar6_r10!$F$2:$F$999,ar6_r10!$A$2:$A$999,$H$14,ar6_r10!$C$2:$C$999,Veda!N$17,ar6_r10!$M$2:$M$999,Veda!$G14) -> 1.59 | O14: =SUMIFS(ar6_r10!$F$2:$F$999,ar6_r10!$A$2:$A$999,$H$14,ar6_r10!$C$2:$C$999,Veda!O$17,ar6_r10!$M$2:$M$999,Veda!$G14) -> 1.73 | T14: =S11 -> 177.03 | U14: =$S$11*J14 -> 185.8815 | V14: =$S$11*K14 -> 207.1251 | W14: =$S$11*L14 -> 228.3687 | X14: =$S$11*M14 -> 251.3826 | Y14: =$S$11*N14 -> 281.4777 | Z14: =$S$11*O14 -> 306.2619 | AG14: 6 | AH14: ts_072 | AI14: =AH14 -> ts_072 | AJ14: =AJ9+1 -> 2
A15: 5 | B15: =_xlfn.TEXTJOIN(CHAR(183),TRUE,D15,TEXT(E15,"$000")) -> high·$200 | C15: =C14+1 -> 7 | D15: high | E15: =E11 -> 200 | G15: Heat growth relative to 2020 | I15: =SUMIFS(ar6_r10!$F$2:$F$999,ar6_r10!$A$2:$A$999,Veda!$E$5,ar6_r10!$C$2:$C$999,Veda!I$17,ar6_r10!$M$2:$M$999,Veda!$G15) -> 0 | J15: =SUMIFS(ar6_r10!$F$2:$F$999,ar6_r10!$A$2:$A$999,$H$14,ar6_r10!$C$2:$C$999,Veda!J$17,ar6_r10!$M$2:$M$999,Veda!$G15) -> 0 | K15: =SUMIFS(ar6_r10!$F$2:$F$999,ar6_r10!$A$2:$A$999,$H$14,ar6_r10!$C$2:$C$999,Veda!K$17,ar6_r10!$M$2:$M$999,Veda!$G15) -> 0 | L15: =SUMIFS(ar6_r10!$F$2:$F$999,ar6_r10!$A$2:$A$999,$H$14,ar6_r10!$C$2:$C$999,Veda!L$17,ar6_r10!$M$2:$M$999,Veda!$G15) -> 0 | M15: =SUMIFS(ar6_r10!$F$2:$F$999,ar6_r10!$A$2:$A$999,$H$14,ar6_r10!$C$2:$C$999,Veda!M$17,ar6_r10!$M$2:$M$999,Veda!$G15) -> 0 | N15: =SUMIFS(ar6_r10!$F$2:$F$999,ar6_r10!$A$2:$A$999,$H$14,ar6_r10!$C$2:$C$999,Veda!N$17,ar6_r10!$M$2:$M$999,Veda!$G15) -> 0 | O15: =SUMIFS(ar6_r10!$F$2:$F$999,ar6_r10!$A$2:$A$999,$H$14,ar6_r10!$C$2:$C$999,Veda!O$17,ar6_r10!$M$2:$M$999,Veda!$G15) -> 0 | AG15: 7 | AH15: ts_144 | AI15: =AH15 -> ts_144 | AJ15: =AJ10+1 -> 2
A16: 5 | B16: =_xlfn.TEXTJOIN(CHAR(183),TRUE,D16,TEXT(E16,"$000")) -> high·$300 | C16: =C15+1 -> 8 | D16: high | E16: =E12 -> 300 | S16: ~TFM_INS-TS | AG16: 8 | AH16: ts_288 | AI16: =AH16 -> ts_288 | AJ16: =AJ11+1 -> 2
A17: 5 | I17: 2020 | J17: =U17 -> 2025 | K17: =V17 -> 2030 | L17: =W17 -> 2035 | M17: =X17 -> 2040 | N17: =Y17 -> 2045 | O17: =Z17 -> 2050 | S17: commodity | T17: 2022 | U17: 2025 | V17: 2030 | W17: 2035 | X17: 2040 | Y17: 2045 | Z17: 2050 | AA17: attribute | AG17: 9 | AH17: s1v1_d | AI17: f2d96 | AJ17: =AJ12+1 -> 2
G18: Hydrogen as a share of electricity | I18: =SUMIFS(ar6_r10!$F$2:$F$999,ar6_r10!$A$2:$A$999,$H$14,ar6_r10!$C$2:$C$999,Veda!I$17,ar6_r10!$M$2:$M$999,Veda!$G18) -> 0 | J18: =SUMIFS(ar6_r10!$F$2:$F$999,ar6_r10!$A$2:$A$999,$H$14,ar6_r10!$C$2:$C$999,Veda!J$17,ar6_r10!$M$2:$M$999,Veda!$G18) -> 0 | K18: =SUMIFS(ar6_r10!$F$2:$F$999,ar6_r10!$A$2:$A$999,$H$14,ar6_r10!$C$2:$C$999,Veda!K$17,ar6_r10!$M$2:$M$999,Veda!$G18) -> 0 | L18: =SUMIFS(ar6_r10!$F$2:$F$999,ar6_r10!$A$2:$A$999,$H$14,ar6_r10!$C$2:$C$999,Veda!L$17,ar6_r10!$M$2:$M$999,Veda!$G18) -> 0 | M18: =SUMIFS(ar6_r10!$F$2:$F$999,ar6_r10!$A$2:$A$999,$H$14,ar6_r10!$C$2:$C$999,Veda!M$17,ar6_r10!$M$2:$M$999,Veda!$G18) -> 0 | N18: =SUMIFS(ar6_r10!$F$2:$F$999,ar6_r10!$A$2:$A$999,$H$14,ar6_r10!$C$2:$C$999,Veda!N$17,ar6_r10!$M$2:$M$999,Veda!$G18) -> 0 | O18: =SUMIFS(ar6_r10!$F$2:$F$999,ar6_r10!$A$2:$A$999,$H$14,ar6_r10!$C$2:$C$999,Veda!O$17,ar6_r10!$M$2:$M$999,Veda!$G18) -> 0 | S18: hydrogen_allsect | T18: =I18*T$14 -> 0 | U18: =J18*U$14 -> 0 | V18: =K18*V$14 -> 0 | W18: =L18*W$14 -> 0 | X18: =M18*X$14 -> 0 | Y18: =N18*Y$14 -> 0 | Z18: =O18*Z$14 -> 0 | AA18: demand | AG18: 10 | AH18: ts_096 | AI18: e96 | AJ18: =AJ13+1 -> 2
G19: Industry electricity share | I19: =SUMIFS(ar6_r10!$F$2:$F$999,ar6_r10!$A$2:$A$999,$H$14,ar6_r10!$C$2:$C$999,Veda!I$17,ar6_r10!$M$2:$M$999,Veda!$G19) -> 0.37 | J19: =SUMIFS(ar6_r10!$F$2:$F$999,ar6_r10!$A$2:$A$999,$H$14,ar6_r10!$C$2:$C$999,Veda!J$17,ar6_r10!$M$2:$M$999,Veda!$G19) -> 0.35 | K19: =SUMIFS(ar6_r10!$F$2:$F$999,ar6_r10!$A$2:$A$999,$H$14,ar6_r10!$C$2:$C$999,Veda!K$17,ar6_r10!$M$2:$M$999,Veda!$G19) -> 0.34 | L19: =SUMIFS(ar6_r10!$F$2:$F$999,ar6_r10!$A$2:$A$999,$H$14,ar6_r10!$C$2:$C$999,Veda!L$17,ar6_r10!$M$2:$M$999,Veda!$G19) -> 0.33 | M19: =SUMIFS(ar6_r10!$F$2:$F$999,ar6_r10!$A$2:$A$999,$H$14,ar6_r10!$C$2:$C$999,Veda!M$17,ar6_r10!$M$2:$M$999,Veda!$G19) -> 0.3 | N19: =SUMIFS(ar6_r10!$F$2:$F$999,ar6_r10!$A$2:$A$999,$H$14,ar6_r10!$C$2:$C$999,Veda!N$17,ar6_r10!$M$2:$M$999,Veda!$G19) -> 0.29 | O19: =SUMIFS(ar6_r10!$F$2:$F$999,ar6_r10!$A$2:$A$999,$H$14,ar6_r10!$C$2:$C$999,Veda!O$17,ar6_r10!$M$2:$M$999,Veda!$G19) -> 0.3 | S19: elc_industry | T19: =I19*T$14 -> 65.5011 | U19: =J19*U$14 -> 65.058525 | V19: =K19*V$14 -> 70.422534 | W19: =L19*W$14 -> 75.361671 | X19: =M19*X$14 -> 75.41478 | Y19: =N19*Y$14 -> 81.628533 | Z19: =O19*Z$14 -> 91.87857 | AA19: demand | AG19: 11 | AH19: s1p1v1_d | AI19: d9d | AJ19: =AJ14+1 -> 3
G20: Residential and commercial electricity share | I20: =SUMIFS(ar6_r10!$F$2:$F$999,ar6_r10!$A$2:$A$999,$H$14,ar6_r10!$C$2:$C$999,Veda!I$17,ar6_r10!$M$2:$M$999,Veda!$G20) -> 0.59 | J20: =SUMIFS(ar6_r10!$F$2:$F$999,ar6_r10!$A$2:$A$999,$H$14,ar6_r10!$C$2:$C$999,Veda!J$17,ar6_r10!$M$2:$M$999,Veda!$G20) -> 0.59 | K20: =SUMIFS(ar6_r10!$F$2:$F$999,ar6_r10!$A$2:$A$999,$H$14,ar6_r10!$C$2:$C$999,Veda!K$17,ar6_r10!$M$2:$M$999,Veda!$G20) -> 0.59 | L20: =SUMIFS(ar6_r10!$F$2:$F$999,ar6_r10!$A$2:$A$999,$H$14,ar6_r10!$C$2:$C$999,Veda!L$17,ar6_r10!$M$2:$M$999,Veda!$G20) -> 0.58 | M20: =SUMIFS(ar6_r10!$F$2:$F$999,ar6_r10!$A$2:$A$999,$H$14,ar6_r10!$C$2:$C$999,Veda!M$17,ar6_r10!$M$2:$M$999,Veda!$G20) -> 0.58 | N20: =SUMIFS(ar6_r10!$F$2:$F$999,ar6_r10!$A$2:$A$999,$H$14,ar6_r10!$C$2:$C$999,Veda!N$17,ar6_r10!$M$2:$M$999,Veda!$G20) -> 0.56 | O20: =SUMIFS(ar6_r10!$F$2:$F$999,ar6_r10!$A$2:$A$999,$H$14,ar6_r10!$C$2:$C$999,Veda!O$17,ar6_r10!$M$2:$M$999,Veda!$G20) -> 0.54 | S20: elc_buildings | T20: =I20*T$14 -> 104.4477 | U20: =J20*U$14 -> 109.67009 | V20: =K20*V$14 -> 122.20381 | W20: =L20*W$14 -> 132.45385 | X20: =M20*X$14 -> 145.80191 | Y20: =N20*Y$14 -> 157.62751 | Z20: =O20*Z$14 -> 165.38143 | AA20: demand | AG20: 12 | AH20: s5p5v5_d | AI20: c15d | AJ20: =AJ15+1 -> 3
G21: Transportation electricity share | I21: =SUMIFS(ar6_r10!$F$2:$F$999,ar6_r10!$A$2:$A$999,$H$14,ar6_r10!$C$2:$C$999,Veda!I$17,ar6_r10!$M$2:$M$999,Veda!$G21) -> 0.03 | J21: =SUMIFS(ar6_r10!$F$2:$F$999,ar6_r10!$A$2:$A$999,$H$14,ar6_r10!$C$2:$C$999,Veda!J$17,ar6_r10!$M$2:$M$999,Veda!$G21) -> 0.05 | K21: =SUMIFS(ar6_r10!$F$2:$F$999,ar6_r10!$A$2:$A$999,$H$14,ar6_r10!$C$2:$C$999,Veda!K$17,ar6_r10!$M$2:$M$999,Veda!$G21) -> 0.04 | L21: =SUMIFS(ar6_r10!$F$2:$F$999,ar6_r10!$A$2:$A$999,$H$14,ar6_r10!$C$2:$C$999,Veda!L$17,ar6_r10!$M$2:$M$999,Veda!$G21) -> 0.06 | M21: =SUMIFS(ar6_r10!$F$2:$F$999,ar6_r10!$A$2:$A$999,$H$14,ar6_r10!$C$2:$C$999,Veda!M$17,ar6_r10!$M$2:$M$999,Veda!$G21) -> 0.07 | N21: =SUMIFS(ar6_r10!$F$2:$F$999,ar6_r10!$A$2:$A$999,$H$14,ar6_r10!$C$2:$C$999,Veda!N$17,ar6_r10!$M$2:$M$999,Veda!$G21) -> 0.08 | O21: =SUMIFS(ar6_r10!$F$2:$F$999,ar6_r10!$A$2:$A$999,$H$14,ar6_r10!$C$2:$C$999,Veda!O$17,ar6_r10!$M$2:$M$999,Veda!$G21) -> 0.08 | S21: elc_transport | T21: =I21*T$14 -> 5.3109 | U21: =T21 -> 5.3109 | V21: =U21 -> 5.3109 | W21: =V21 -> 5.3109 | X21: =W21 -> 5.3109 | Y21: =X21 -> 5.3109 | Z21: =Y21 -> 5.3109 | AA21: demand | AC21: non-road transport demand assumed to be constant | AJ21: =AJ16+1 -> 3
S22: elc_roadtransport | T22: =T14-SUM(T19:T21) -> 1.7703 | U22: =U14-SUM(U19:U21) -> 5.84199 | V22: =V14-SUM(V19:V21) -> 9.187857 | W22: =W14-SUM(W19:W21) -> 15.242283 | X22: =X14-SUM(X19:X21) -> 24.855012 | Y22: =Y14-SUM(Y19:Y21) -> 36.910755 | Z22: =Z14-SUM(Z19:Z21) -> 43.691004 | AA22: demand | AJ22: =AJ17+1 -> 3
S23: HET | T23: =S12 -> 0 | U23: =$S$12*J15 -> 0 | V23: =$S$12*K15 -> 0 | W23: =$S$12*L15 -> 0 | X23: =$S$12*M15 -> 0 | Y23: =$S$12*N15 -> 0 | Z23: =$S$12*O15 -> 0 | AA23: demand | AJ23: =AJ18+1 -> 3
G24: CO2 price | H24: =VLOOKUP(E5,$K$3:$L$6,2,FALSE) -> C7 | I24: 0 | J24: 0 | K24: =SUMIFS(ar6_r10!$F$2:$F$999,ar6_r10!$A$2:$A$999,$H$24,ar6_r10!$C$2:$C$999,Veda!K$17,ar6_r10!$M$2:$M$999,Veda!$G24) -> 0 | L24: =SUMIFS(ar6_r10!$F$2:$F$999,ar6_r10!$A$2:$A$999,$H$24,ar6_r10!$C$2:$C$999,Veda!L$17,ar6_r10!$M$2:$M$999,Veda!$G24) -> 0 | M24: =SUMIFS(ar6_r10!$F$2:$F$999,ar6_r10!$A$2:$A$999,$H$24,ar6_r10!$C$2:$C$999,Veda!M$17,ar6_r10!$M$2:$M$999,Veda!$G24) -> 0 | N24: =SUMIFS(ar6_r10!$F$2:$F$999,ar6_r10!$A$2:$A$999,$H$24,ar6_r10!$C$2:$C$999,Veda!N$17,ar6_r10!$M$2:$M$999,Veda!$G24) -> 0 | O24: =SUMIFS(ar6_r10!$F$2:$F$999,ar6_r10!$A$2:$A$999,$H$24,ar6_r10!$C$2:$C$999,Veda!O$17,ar6_r10!$M$2:$M$999,Veda!$G24) -> 0 | S24: co2net | U24: 0 | V24: =K24/1000 -> 0 | W24: =L24/1000 -> 0 | X24: =M24/1000 -> 0 | Y24: =N24/1000 -> 0 | Z24: =O24/1000 -> 0 | AA24: com_taxnet | AJ24: =AJ19+1 -> 4
AJ25: =AJ20+1 -> 4
S26: ~TFM_INS-TS | AJ26: =AJ21+1 -> 4
S27: process | T27: =T17 -> 2022 | U27: =U17 -> 2025 | V27: =V17 -> 2030 | W27: =W17 -> 2035 | X27: =X17 -> 2040 | Y27: =Y17 -> 2045 | Z27: =Z17 -> 2050 | AA27: attribute | AB27: limtype | AJ27: =AJ22+1 -> 4
Q28: =SUMIFS(iea_data!G3:G9999,iea_data!$B$3:$B$9999,Veda!$S$10) -> 15.24 | S28: Trd_electricity import | T28: =Q28 -> 15.24 | AA28: ACT_BND | AB28: FX | AJ28: =AJ23+1 -> 4
Q29: =SUMIFS(iea_data!H3:H9999,iea_data!$B$3:$B$9999,Veda!$S$10) -> -16.91 | S29: Trd_electricity export | T29: =-1*Q29 -> 16.91 | AA29: ACT_BND | AB29: FX | AJ29: =AJ24+1 -> 5
AJ30: =AJ25+1 -> 5
AJ31: =AJ26+1 -> 5
AJ32: =AJ27+1 -> 5
AJ33: =AJ28+1 -> 5
AJ34: =AJ29+1 -> 6
AJ35: =AJ30+1 -> 6
G36: C7 | AJ36: =AJ31+1 -> 6
G37: Gas Price | I37: =SUMIFS(ar6_r10!$F$2:$F$999,ar6_r10!$A$2:$A$999,Veda!$G$36,ar6_r10!$C$2:$C$999,Veda!I$17,ar6_r10!$M$2:$M$999,Veda!$G37) -> 1 | J37: =SUMIFS(ar6_r10!$F$2:$F$999,ar6_r10!$A$2:$A$999,Veda!$G$36,ar6_r10!$C$2:$C$999,Veda!J$17,ar6_r10!$M$2:$M$999,Veda!$G37) -> 1.07 | K37: =SUMIFS(ar6_r10!$F$2:$F$999,ar6_r10!$A$2:$A$999,Veda!$G$36,ar6_r10!$C$2:$C$999,Veda!K$17,ar6_r10!$M$2:$M$999,Veda!$G37) -> 1.24 | L37: =SUMIFS(ar6_r10!$F$2:$F$999,ar6_r10!$A$2:$A$999,Veda!$G$36,ar6_r10!$C$2:$C$999,Veda!L$17,ar6_r10!$M$2:$M$999,Veda!$G37) -> 1.15 | M37: =SUMIFS(ar6_r10!$F$2:$F$999,ar6_r10!$A$2:$A$999,Veda!$G$36,ar6_r10!$C$2:$C$999,Veda!M$17,ar6_r10!$M$2:$M$999,Veda!$G37) -> 1.25 | N37: =SUMIFS(ar6_r10!$F$2:$F$999,ar6_r10!$A$2:$A$999,Veda!$G$36,ar6_r10!$C$2:$C$999,Veda!N$17,ar6_r10!$M$2:$M$999,Veda!$G37) -> 1.17 | O37: =SUMIFS(ar6_r10!$F$2:$F$999,ar6_r10!$A$2:$A$999,Veda!$G$36,ar6_r10!$C$2:$C$999,Veda!O$17,ar6_r10!$M$2:$M$999,Veda!$G37) -> 1.34 | AJ37: =AJ32+1 -> 6
G38: Coal Price | I38: =SUMIFS(ar6_r10!$F$2:$F$999,ar6_r10!$A$2:$A$999,Veda!$G$36,ar6_r10!$C$2:$C$999,Veda!I$17,ar6_r10!$M$2:$M$999,Veda!$G38) -> 1 | J38: =SUMIFS(ar6_r10!$F$2:$F$999,ar6_r10!$A$2:$A$999,Veda!$G$36,ar6_r10!$C$2:$C$999,Veda!J$17,ar6_r10!$M$2:$M$999,Veda!$G38) -> 1.02 | K38: =SUMIFS(ar6_r10!$F$2:$F$999,ar6_r10!$A$2:$A$999,Veda!$G$36,ar6_r10!$C$2:$C$999,Veda!K$17,ar6_r10!$M$2:$M$999,Veda!$G38) -> 1.06 | L38: =SUMIFS(ar6_r10!$F$2:$F$999,ar6_r10!$A$2:$A$999,Veda!$G$36,ar6_r10!$C$2:$C$999,Veda!L$17,ar6_r10!$M$2:$M$999,Veda!$G38) -> 1.07 | M38: =SUMIFS(ar6_r10!$F$2:$F$999,ar6_r10!$A$2:$A$999,Veda!$G$36,ar6_r10!$C$2:$C$999,Veda!M$17,ar6_r10!$M$2:$M$999,Veda!$G38) -> 1.08 | N38: =SUMIFS(ar6_r10!$F$2:$F$999,ar6_r10!$A$2:$A$999,Veda!$G$36,ar6_r10!$C$2:$C$999,Veda!N$17,ar6_r10!$M$2:$M$999,Veda!$G38) -> 1.1 | O38: =SUMIFS(ar6_r10!$F$2:$F$999,ar6_r10!$A$2:$A$999,Veda!$G$36,ar6_r10!$C$2:$C$999,Veda!O$17,ar6_r10!$M$2:$M$999,Veda!$G38) -> 1.12 | AJ38: =AJ33+1 -> 6
G39: Oil Price | I39: =SUMIFS(ar6_r10!$F$2:$F$999,ar6_r10!$A$2:$A$999,Veda!$G$36,ar6_r10!$C$2:$C$999,Veda!I$17,ar6_r10!$M$2:$M$999,Veda!$G39) -> 1 | J39: =SUMIFS(ar6_r10!$F$2:$F$999,ar6_r10!$A$2:$A$999,Veda!$G$36,ar6_r10!$C$2:$C$999,Veda!J$17,ar6_r10!$M$2:$M$999,Veda!$G39) -> 1.01 | K39: =SUMIFS(ar6_r10!$F$2:$F$999,ar6_r10!$A$2:$A$999,Veda!$G$36,ar6_r10!$C$2:$C$999,Veda!K$17,ar6_r10!$M$2:$M$999,Veda!$G39) -> 1.11 | L39: =SUMIFS(ar6_r10!$F$2:$F$999,ar6_r10!$A$2:$A$999,Veda!$G$36,ar6_r10!$C$2:$C$999,Veda!L$17,ar6_r10!$M$2:$M$999,Veda!$G39) -> 1.01 | M39: =SUMIFS(ar6_r10!$F$2:$F$999,ar6_r10!$A$2:$A$999,Veda!$G$36,ar6_r10!$C$2:$C$999,Veda!M$17,ar6_r10!$M$2:$M$999,Veda!$G39) -> 1.01 | N39: =SUMIFS(ar6_r10!$F$2:$F$999,ar6_r10!$A$2:$A$999,Veda!$G$36,ar6_r10!$C$2:$C$999,Veda!N$17,ar6_r10!$M$2:$M$999,Veda!$G39) -> 1.04 | O39: =SUMIFS(ar6_r10!$F$2:$F$999,ar6_r10!$A$2:$A$999,Veda!$G$36,ar6_r10!$C$2:$C$999,Veda!O$17,ar6_r10!$M$2:$M$999,Veda!$G39) -> 1.14 | AJ39: =AJ34+1 -> 7
G40: Biomass Price | I40: =SUMIFS(ar6_r10!$F$2:$F$999,ar6_r10!$A$2:$A$999,Veda!$G$36,ar6_r10!$C$2:$C$999,Veda!I$17,ar6_r10!$M$2:$M$999,Veda!$G40) -> 1 | J40: =SUMIFS(ar6_r10!$F$2:$F$999,ar6_r10!$A$2:$A$999,Veda!$G$36,ar6_r10!$C$2:$C$999,Veda!J$17,ar6_r10!$M$2:$M$999,Veda!$G40) -> 0.96 | K40: =SUMIFS(ar6_r10!$F$2:$F$999,ar6_r10!$A$2:$A$999,Veda!$G$36,ar6_r10!$C$2:$C$999,Veda!K$17,ar6_r10!$M$2:$M$999,Veda!$G40) -> 1.04 | L40: =SUMIFS(ar6_r10!$F$2:$F$999,ar6_r10!$A$2:$A$999,Veda!$G$36,ar6_r10!$C$2:$C$999,Veda!L$17,ar6_r10!$M$2:$M$999,Veda!$G40) -> 1.04 | M40: =SUMIFS(ar6_r10!$F$2:$F$999,ar6_r10!$A$2:$A$999,Veda!$G$36,ar6_r10!$C$2:$C$999,Veda!M$17,ar6_r10!$M$2:$M$999,Veda!$G40) -> 0.98 | N40: =SUMIFS(ar6_r10!$F$2:$F$999,ar6_r10!$A$2:$A$999,Veda!$G$36,ar6_r10!$C$2:$C$999,Veda!N$17,ar6_r10!$M$2:$M$999,Veda!$G40) -> 0.99 | O40: =SUMIFS(ar6_r10!$F$2:$F$999,ar6_r10!$A$2:$A$999,Veda!$G$36,ar6_r10!$C$2:$C$999,Veda!O$17,ar6_r10!$M$2:$M$999,Veda!$G40) -> 1 | AJ40: =AJ35+1 -> 7
...

Sheet fuel_prices
A9: Fuel Prices
A10: iso | B10: gas_low | C10: gas_high | D10: coal_low | E10: coal_high | F10: oil_low | G10: oil_high | H10: bioenergy_low | I10: bioenergy_high | J10: Notes
A11: POL | B11: 27.4 | C11: 39.4 | D11: 10.7 | E11: 13.7 | F11: 48 | G11: 58 | H11: 22 | I11: 30 | J11: Pipeline gas, coal & forest resources

Sheet iea_data
A9: IEA Baseline Data
A10: iso | B10: year | C10: industry_twh | D10: buildings_agri_twh | E10: nonroad_transport_twh | F10: road_transport_twh | G10: imports_twh | H10: exports_twh | I10: total_production_twh | J10: chp_heat_twh | K10: heat_tfc_twh
A11: POL | B11: 2000 | C11: 75.85 | D11: 53.54 | E11: 4.31 | F11: 0.02 | G11: 3.29 | H11: -9.66 | I11: 143.17 | J11: 0 | K11: 0
A12: POL | B12: 2001 | C12: 74.36 | D12: 55.12 | E12: 4.27 | F12: 0.02 | G12: 4.31 | H12: -11.04 | I12: 143.72 | J12: 0 | K12: 0
A13: POL | B13: 2002 | C13: 73.3 | D13: 54.71 | E13: 4.29 | F13: 0.02 | G13: 4.47 | H13: -11.54 | I13: 142.5 | J13: 0 | K13: 0
A14: POL | B14: 2003 | C14: 75.86 | D14: 56.23 | E14: 4.37 | F14: 0.02 | G14: 4.99 | H14: -15.15 | I14: 150.01 | J14: 0 | K14: 0
A15: POL | B15: 2004 | C15: 78.18 | D15: 57.95 | E15: 3.88 | F15: 0.02 | G15: 5.31 | H15: -14.6 | I15: 152.55 | J15: 0 | K15: 0
A16: POL | B16: 2005 | C16: 77.15 | D16: 60.1 | E16: 3.55 | F16: 0.02 | G16: 5 | H16: -16.19 | I16: 155.36 | J16: 0 | K16: 0
A17: POL | B17: 2006 | C17: 78.91 | D17: 64.7 | E17: 3.1 | F17: 0.02 | G17: 4.79 | H17: -15.78 | I17: 160.76 | J17: 0 | K17: 0
A18: POL | B18: 2007 | C18: 82.1 | D18: 65.06 | E18: 3.25 | F18: 0.02 | G18: 7.76 | H18: -13.11 | I18: 158.76 | J18: 0 | K18: 0
A19: POL | B19: 2008 | C19: 78.39 | D19: 69.83 | E19: 3.17 | F19: 0.02 | G19: 9.03 | H19: -9.7 | I19: 154.71 | J19: 0 | K19: 0
A20: POL | B20: 2009 | C20: 73.96 | D20: 69.69 | E20: 2.86 | F20: 0.02 | G20: 7.4 | H20: -9.59 | I20: 151.12 | J20: 0 | K20: 0
A21: POL | B21: 2010 | C21: 76.11 | D21: 73.9 | E21: 2.96 | F21: 0.02 | G21: 6.31 | H21: -7.66 | I21: 157.09 | J21: 0 | K21: 0
A22: POL | B22: 2011 | C22: 78.38 | D22: 74.04 | E22: 2.96 | F22: 0.02 | G22: 6.78 | H22: -12.02 | I22: 163.12 | J22: 0 | K22: 0
... A33: POL | B33: 2022 | C33: 83.2 | D33: 84.78 | E33: 3.32 | F33: 0.17 | G33: 15.24 | H33: -16.91 | I33: 178.7 | J33: 0 | K33: 0

Sheet ar6_r10
A9: AR6 Scenario Drivers
A10: Category | B10: Region | C10: Year | D10: count | E10: mean | F10: median | G10: std | H10: min | I10: max | J10: q25 | K10: q75 | L10: category_description | M10: attribute
A11: C1 | B11: R10EUROPE | C11: 2020 | D11: 60 | E11: 8.68 | F11: 6.87 | G11: 10.43 | H11: 0 | I11: 55.17 | J11: 0 | K11: 13.64 | L11: Limit warming to 1.5°C (>50%) with no or limited overshoot | M11: CO2 price
A12: C1 | B12: R10EUROPE | C12: 2025 | D12: 60 | E12: 190.52 | F12: 181.51 | G12: 136.23 | H12: 1.81 | I12: 626.48 | J12: 115.48 | K12: 238.58 | L12: Limit warming to 1.5°C (>50%) with no or limited overshoot | M12: CO2 price
A13: C1 | B13: R10EUROPE | C13: 2030 | D13: 60 | E13: 268.18 | F13: 241.69 | G13: 134.29 | H13: 1.27 | I13: 673.46 | J13: 182.47 | K13: 329.7 | L13: Limit warming to 1.5°C (>50%) with no or limited overshoot | M13: CO2 price
A14: C1 | B14: R10EUROPE | C14: 2035 | D14: 60 | E14: 363.27 | F14: 339.03 | G14: 173.79 | H14: 14.37 | I14: 859.53 | J14: 227.05 | K14: 483.38 | L14: Limit warming to 1.5°C (>50%) with no or limited overshoot | M14: CO2 price
A15: C1 | B15: R10EUROPE | C15: 2040 | D15: 60 | E15: 471.65 | F15: 410.28 | G15: 224.31 | H15: 162.1 | I15: 1097.01 | J15: 298.63 | K15: 622.14 | L15: Limit warming to 1.5°C (>50%) with no or limited overshoot | M15: CO2 price
A16: C1 | B16: R10EUROPE | C16: 2045 | D16: 60 | E16: 565.69 | F16: 494.2 | G16: 256.15 | H16: 193.42 | I16: 1269.88 | J16: 352.78 | K16: 748.01 | L16: Limit warming to 1.5°C (>50%) with no or limited overshoot | M16: CO2 price
A17: C1 | B17: R10EUROPE | C17: 2050 | D17: 60 | E17: 647.44 | F17: 635.43 | G17: 273.56 | H17: 209.76 | I17: 1170.26 | J17: 409.79 | K17: 887.68 | L17: Limit warming to 1.5°C (>50%) with no or limited overshoot | M17: CO2 price
A18: C2 | B18: R10EUROPE | C18: 2020 | D18: 86 | E18: 6.44 | F18: 0 | G18: 8.34 | H18: 0 | I18: 24.5 | J18: 0 | K18: 12.68 | L18: Limit warming to 1.5°C (>67%) with high overshoot | M18: CO2 price
A19: C2 | B19: R10EUROPE | C19: 2025 | D19: 75 | E19: 63.21 | F19: 44.89 | G19: 56.62 | H19: 3.21 | I19: 273 | J19: 27.09 | K19: 77.31 | L19: Limit warming to 1.5°C (>67%) with high overshoot | M19: CO2 price
A20: C2 | B20: R10EUROPE | C20: 2030 | D20: 86 | E20: 85.48 | F20: 63.36 | G20: 73.46 | H20: 0 | I20: 409.5 | J20: 50 | K20: 111.1 | L20: Limit warming to 1.5°C (>67%) with high overshoot | M20: CO2 price
A21: C2 | B21: R10EUROPE | C21: 2035 | D21: 75 | E21: 208.71 | F21: 154.82 | G21: 291.78 | H21: 60.83 | I21: 2037.12 | J21: 93.79 | K21: 206.26 | L21: Limit warming to 1.5°C (>67%) with high overshoot | M21: CO2 price
A22: C2 | B22: R10EUROPE | C22: 2040 | D22: 86 | E22: 253.33 | F22: 172.09 | G22: 359.35 | H22: 0 | I22: 2600 | J22: 119.07 | K22: 259.4 | L22: Limit warming to 1.5°C (>67%) with high overshoot | M22: CO2 price
... A221: C1 | B221: R10EUROPE | C221: 2020 | D221: 33 | E221: 1 | F221: 1 | G221: 0 | H221: 1 | I221: 1 | J221: 1 | K221: 1 | L221: Limit warming to 1.5°C (>50%) with no or limited overshoot | M221: Gas price
A222: C1 | B222: R10EUROPE | C222: 2025 | D222: 34 | E222: #NUM! | F222: 2.42 | H222: 1.18 | I222: #NUM! | J222: 2.01 | K222: 2.75 | L222: Limit warming to 1.5°C (>50%) with no or limited overshoot | M222: Gas price
A223: C1 | B223: R10EUROPE | C223: 2030 | D223: 34 | E223: #NUM! | F223: 3.1 | H223: 1.71 | I223: #NUM! | J223: 2.38 | K223: 3.46 | L223: Limit warming to 1.5°C (>50%) with no or limited overshoot | M223: Gas price
A224: C1 | B224: R10EUROPE | C224: 2035 | D224: 34 | E224: #NUM! | F224: 3.54 | H224: 1.91 | I224: #NUM! | J224: 2.66 | K224: 4.16 | L224: Limit warming to 1.5°C (>50%) with no or limited overshoot | M224: Gas price
A225: C1 | B225: R10EUROPE | C225: 2040 | D225: 34 | E225: #NUM! | F225: 4.1 | H225: 2.27 | I225: #NUM! | J225: 2.96 | K225: 4.52 | L225: Limit warming to 1.5°C (>50%) with no or limited overshoot | M225: Gas price
A226: C1 | B226: R10EUROPE | C226: 2045 | D226: 34 | E226: #NUM! | F226: 3.86 | H226: 2.54 | I226: #NUM! | J226: 3.3 | K226: 4.89 | L226: Limit warming to 1.5°C (>50%) with no or limited overshoot | M226: Gas price
A227: C1 | B227: R10EUROPE | C227: 2050 | D227: 34 | E227: #NUM! | F227: 3.59 | H227: 2.73 | I227: #NUM! | J227: 3.07 | K227: 4.06 | L227: Limit warming to 1.5°C (>50%) with no or limited overshoot | M227: Gas price
A228: C2 | B228: R10EUROPE | C228: 2020 | D228: 43 | E228: 1 | F228: 1 | G228: 0 | H228: 1 | I228: 1 | J228: 1 | K228: 1 | L228: Limit warming to 1.5°C (>67%) with high overshoot | M228: Gas price
A229: C2 | B229: R10EUROPE | C229: 2025 | D229: 44 | E229: #NUM! | F229: 1.22 | H229: 0 | I229: #NUM! | J229: 1.13 | K229: 1.35 | L229: Limit warming to 1.5°C (>67%) with high overshoot | M229: Gas price
A230: C2 | B230: R10EUROPE | C230: 2030 | D230: 44 | E230: #NUM! | F230: 1.5 | H230: 0 | I230: #NUM! | J230: 1.31 | K230: 1.83 | L230: Limit warming to 1.5°C (>67%) with high overshoot | M230: Gas price
A231: C2 | B231: R10EUROPE | C231: 2035 | D231: 44 | E231: #NUM! | F231: 2.12 | H231: 0 | I231: #NUM! | J231: 1.68 | K231: 2.46 | L231: Limit warming to 1.5°C (>67%) with high overshoot | M231: Gas price
A232: C2 | B232: R10EUROPE | C232: 2040 | D232: 44 | E232: #NUM! | F232: 2.5 | H232: 0 | I232: #NUM! | J232: 2 | K232: 2.94 | L232: Limit warming to 1.5°C (>67%) with high overshoot | M232: Gas price
A233: C2 | B233: R10EUROPE | C233: 2045 | D233: 44 | E233: #NUM! | F233: 2.79 | H233: 0 | I233: #NUM! | J233: 2.08 | K233: 3.44 | L233: Limit warming to 1.5°C (>67%) with high overshoot | M233: Gas price
A234: C2 | B234: R10EUROPE | C234: 2050 | D234: 44 | E234: #NUM! | F234: 2.95 | H234: 0 | I234: #NUM! | J234: 2.49 | K234: 3.78 | L234: Limit warming to 1.5°C (>67%) with high overshoot | M234: Gas price
A235: C3 | B235: R10EUROPE | C235: 2020 | D235: 103 | E235: 1 | F235: 1 | G235: 0 | H235: 1 | I235: 1 | J235: 1 | K235: 1 | L235: Limit warming to 2°C (>67%) with higher action post-2030 | M235: Gas price
A236: C3 | B236: R10EUROPE | C236: 2025 | D236: 112 | E236: #NUM! | F236: 1.41 | H236: 0.98 | I236: #NUM! | J236: 1.23 | K236: 1.96 | L236: Limit warming to 2°C (>67%) with higher action post-2030 | M236: Gas price
A237: C3 | B237: R10EUROPE | C237: 2030 | D237: 112 | E237: #NUM! | F237: 2.04 | H237: 1.05 | I237: #NUM! | J237: 1.52 | K237: 2.55 | L237: Limit warming to 2°C (>67%) with higher action post-2030 | M237: Gas price
A238: C3 | B238: R10EUROPE | C238: 2035 | D238: 112 | E238: #NUM! | F238: 2.4 | H238: 1.05 | I238: #NUM! | J238: 1.71 | K238: 3.14 | L238: Limit warming to 2°C (>67%) with higher action post-2030 | M238: Gas price
A239: C3 | B239: R10EUROPE | C239: 2040 | D239: 112 | E239: #NUM! | F239: 2.6 | H239: 1.06 | I239: #NUM! | J239: 1.85 | K239: 3.74 | L239: Limit warming to 2°C (>67%) with higher action post-2030 | M239: Gas price
A240: C3 | B240: R10EUROPE | C240: 2045 | D240: 112 | E240: #NUM! | F240: 2.85 | H240: 1.08 | I240: #NUM! | J240: 2 | K240: 4.28 | L240: Limit warming to 2°C (>67%) with higher action post-2030 | M240: Gas price
A241: C3 | B241: R10EUROPE | C241: 2050 | D241: 112 | E241: #NUM! | F241: 2.97 | H241: 0 | I241: #NUM! | J241: 2.15 | K241: 4.51 | L241: Limit warming to 2°C (>67%) with higher action post-2030 | M241: Gas price
A242: C4 | B242: R10EUROPE | C242: 2020 | D242: 27 | E242: 1 | F242: 1 | G242: 0 | H242: 1 | I242: 1 | J242: 1 | K242: 1 | L242: Limit warming to 2°C (>50%) with immediate action | M242: Gas price
A243: C4 | B243: R10EUROPE | C243: 2025 | D243: 27 | E243: 1.33 | F243: 1.31 | G243: 0.18 | H243: 1.06 | I243: 1.66 | J243: 1.22 | K243: 1.45 | L243: Limit warming to 2°C (>50%) with immediate action | M243: Gas price
A244: C4 | B244: R10EUROPE | C244: 2030 | D244: 27 | E244: 1.84 | F244: 2.02 | G244: 0.28 | H244: 1.24 | I244: 2.17 | J244: 1.52 | K244: 2.07 | L244: Limit warming to 2°C (>50%) with immediate action | M244: Gas price
A245: C4 | B245: R10EUROPE | C245: 2035 | D245: 27 | E245: 1.84 | F245: 1.96 | G245: 0.41 | H245: 1.19 | I245: 2.46 | J245: 1.42 | K245: 2.11 | L245: Limit warming to 2°C (>50%) with immediate action | M245: Gas price
A246: C4 | B246: R10EUROPE | C246: 2040 | D246: 27 | E246: 2.12 | F246: 2.22 | G246: 0.47 | H246: 1.41 | I246: 2.78 | J246: 1.54 | K246: 2.43 | L246: Limit warming to 2°C (>50%) with immediate action | M246: Gas price
...
